Workbook
Name _Toc255726701: #REF!

Sheet القائمة
A3: CODE | B3: التصنيف الفرعى | C3: التصنيف الرئيسى | D3: التبويب | E3: القائمة | F3: م
A4: 101 | C4: الصندوق | D4: النقدية ومافي حكمها | E4: مركز مالى | F4: 1
A5: 102 | C5: البنوك | D5: النقدية ومافي حكمها | E5: مركز مالى | F5: 1
A6: 103 | C6: شيكات تحت التحصيل | D6: النقدية ومافي حكمها | E6: مركز مالى | F6: 1
A7: 201 | C7: ذمم العملاء | D7: الذمم المدينة | E7: مركز مالى | F7: 2
A8: 202 | C8: الانخفاض فى قيمة العملاء | D8: الذمم المدينة | E8: مركز مالى | F8: 2
A9: 301 | C9: المدينون المتنوعون | D9: أرصدة مدينة أخري | E9: مركز مالى | F9: 3
A10: 302 | C10: ايرادات مستحقة | D10: أرصدة مدينة أخري | E10: مركز مالى | F10: 3
A11: 303 | C11: المصروفات المدفوعة مقدماً | D11: أرصدة مدينة أخري | E11: مركز مالى | F11: 3
A12: 304 | C12: ذمم العاملين | D12: أرصدة مدينة أخري | E12: مركز مالى | F12: 3
A13: 305 | C13: عهد عاملين | D13: أرصدة مدينة أخري | E13: مركز مالى | F13: 3
A14: 306 | C14: تأمينات لدى الغير | D14: أرصدة مدينة أخري | E14: مركز مالى | F14: 3
A15: 307 | C15: خطابات الضمان | D15: أرصدة مدينة أخري | E15: مركز مالى | F15: 3
... A57: 2604 | C57: مردودات مشتريات | D57: تكلفة الايرادات | E57: دخل | F57: 26
A58: 2605 | B58: رواتب وأجور وما في حكمها | C58: مصاريف التشغيل | D58: تكلفة الايرادات | E58: دخل | F58: 26
A59: 2606 | B59: تأمينات إجتماعية | C59: مصاريف التشغيل | D59: تكلفة الايرادات | E59: دخل | F59: 26
A60: 2607 | B60: تأمين طبي وعلاج | C60: مصاريف التشغيل | D60: تكلفة الايرادات | E60: دخل | F60: 26
A61: 2608 | B61: سفر ونقل وانتقالات | C61: مصاريف التشغيل | D61: تكلفة الايرادات | E61: دخل | F61: 26
A62: 2609 | B62: مكافأة نهاية الخدمة | C62: مصاريف التشغيل | D62: تكلفة الايرادات | E62: دخل | F62: 26
A63: 2610 | B63: الإيجارات | C63: مصاريف التشغيل | D63: تكلفة الايرادات | E63: دخل | F63: 26
A64: 2611 | B64: رسوم حكومية واشتراكات | C64: مصاريف التشغيل | D64: تكلفة الايرادات | E64: دخل | F64: 26
A65: 2612 | B65: كهرباء ومياه و مرافق | C65: مصاريف التشغيل | D65: تكلفة الايرادات | E65: دخل | F65: 26
A66: 2613 | B66: قرطاسية ومطبوعات | C66: مصاريف التشغيل | D66: تكلفة الايرادات | E66: دخل | F66: 26
A67: 2614 | B67: بريد وهاتف وانترنت | C67: مصاريف التشغيل | D67: تكلفة الايرادات | E67: دخل | F67: 26
A68: 2615 | B68: زيوت ومحروقات | C68: مصاريف التشغيل | D68: تكلفة الايرادات | E68: دخل | F68: 26
A69: 2616 | B69: صيانة وإصلاح | C69: مصاريف التشغيل | D69: تكلفة الايرادات | E69: دخل | F69: 26
... A108: 2819 | B108: مصاريف متنوعة | C108: المصروفات العمومية والادارية | D108: المصروفات العمومية والادارية | E108: دخل | F108: 28
A109: 2901 | C109: ايرادات متنوعة | D109: ايرادات اخرى | E109: دخل | F109: 29
A110: 2902 | C110: ارباح او خسائر بيع اصول | D110: ايرادات اخرى | E110: دخل | F110: 29
A111: 2903 | C111: مخصصات انتفى الغرض منها | D111: ايرادات اخرى | E111: دخل | F111: 29
A112: 3001 | C112: استهلاك العقارات والآلات والمعدات | D112: استهلاك العقارات والآلات والمعدات | E112: دخل | F112: 30

Sheet الميزان
A1: اكتب كود الحساب | B1: لا يتم تغييرها | C1: لا يتم تغييرها | D1: لا يتم تغييرها | E1: لا يتم تغييرها | F1: لا يتم تغييرها | P1: لا يتم تغييرها | Q1: لا يتم تغييرها
A2: CODE | B2: التصنيف الفرعى العام الحالى | C2: التصنيف الرئيسى العام الحالى | D2: التبويب العام الحالى | E2: القائمة | F2: م | G2: الفرع | H2: الكود | I2: اسم الحساب | J2: مدين اول | K2: دائن اول | L2: حركة مدينة | M2: حركة دائنة | N2: مدين اخر | O2: دائن اخر | P2: رصيد اول | Q2: رصيد اخر
B3: =IFERROR(VLOOKUP(A3,القائمة!$A$3:$F$112,2,FALSE),"") | C3: =IFERROR(VLOOKUP(A3,القائمة!$A$3:$F$112,3,FALSE),"") | D3: =IFERROR(VLOOKUP(A3,القائمة!$A$3:$F$112,4,FALSE),"") | E3: =IFERROR(VLOOKUP(A3,القائمة!$A$3:$F$112,5,FALSE),"") | F3: =IFERROR(VLOOKUP(A3,القائمة!$A$3:$F$112,6,FALSE),"") | P3: =J3-K3 -> 0 | Q3: =+P3+L3-M3 -> 0
B4: =IFERROR(VLOOKUP(A4,القائمة!$A$3:$F$112,2,FALSE),"") | C4: =IFERROR(VLOOKUP(A4,القائمة!$A$3:$F$112,3,FALSE),"") | D4: =IFERROR(VLOOKUP(A4,القائمة!$A$3:$F$112,4,FALSE),"") | E4: =IFERROR(VLOOKUP(A4,القائمة!$A$3:$F$112,5,FALSE),"") | F4: =IFERROR(VLOOKUP(A4,القائمة!$A$3:$F$112,6,FALSE),"") | P4: =J4-K4 -> 0 | Q4: =+P4+L4-M4 -> 0
B5: =IFERROR(VLOOKUP(A5,القائمة!$A$3:$F$112,2,FALSE),"") | C5: =IFERROR(VLOOKUP(A5,القائمة!$A$3:$F$112,3,FALSE),"") | D5: =IFERROR(VLOOKUP(A5,القائمة!$A$3:$F$112,4,FALSE),"") | E5: =IFERROR(VLOOKUP(A5,القائمة!$A$3:$F$112,5,FALSE),"") | F5: =IFERROR(VLOOKUP(A5,القائمة!$A$3:$F$112,6,FALSE),"") | P5: =J5-K5 -> 0 | Q5: =+P5+L5-M5 -> 0
B6: =IFERROR(VLOOKUP(A6,القائمة!$A$3:$F$112,2,FALSE),"") | C6: =IFERROR(VLOOKUP(A6,القائمة!$A$3:$F$112,3,FALSE),"") | D6: =IFERROR(VLOOKUP(A6,القائمة!$A$3:$F$112,4,FALSE),"") | E6: =IFERROR(VLOOKUP(A6,القائمة!$A$3:$F$112,5,FALSE),"") | F6: =IFERROR(VLOOKUP(A6,القائمة!$A$3:$F$112,6,FALSE),"") | P6: =J6-K6 -> 0 | Q6: =+P6+L6-M6 -> 0
B7: =IFERROR(VLOOKUP(A7,القائمة!$A$3:$F$112,2,FALSE),"") | C7: =IFERROR(VLOOKUP(A7,القائمة!$A$3:$F$112,3,FALSE),"") | D7: =IFERROR(VLOOKUP(A7,القائمة!$A$3:$F$112,4,FALSE),"") | E7: =IFERROR(VLOOKUP(A7,القائمة!$A$3:$F$112,5,FALSE),"") | F7: =IFERROR(VLOOKUP(A7,القائمة!$A$3:$F$112,6,FALSE),"") | P7: =J7-K7 -> 0 | Q7: =+P7+L7-M7 -> 0
B8: =IFERROR(VLOOKUP(A8,القائمة!$A$3:$F$112,2,FALSE),"") | C8: =IFERROR(VLOOKUP(A8,القائمة!$A$3:$F$112,3,FALSE),"") | D8: =IFERROR(VLOOKUP(A8,القائمة!$A$3:$F$112,4,FALSE),"") | E8: =IFERROR(VLOOKUP(A8,القائمة!$A$3:$F$112,5,FALSE),"") | F8: =IFERROR(VLOOKUP(A8,القائمة!$A$3:$F$112,6,FALSE),"") | P8: =J8-K8 -> 0 | Q8: =+P8+L8-M8 -> 0
B9: =IFERROR(VLOOKUP(A9,القائمة!$A$3:$F$112,2,FALSE),"") | C9: =IFERROR(VLOOKUP(A9,القائمة!$A$3:$F$112,3,FALSE),"") | D9: =IFERROR(VLOOKUP(A9,القائمة!$A$3:$F$112,4,FALSE),"") | E9: =IFERROR(VLOOKUP(A9,القائمة!$A$3:$F$112,5,FALSE),"") | F9: =IFERROR(VLOOKUP(A9,القائمة!$A$3:$F$112,6,FALSE),"") | P9: =J9-K9 -> 0 | Q9: =+P9+L9-M9 -> 0
B10: =IFERROR(VLOOKUP(A10,القائمة!$A$3:$F$112,2,FALSE),"") | C10: =IFERROR(VLOOKUP(A10,القائمة!$A$3:$F$112,3,FALSE),"") | D10: =IFERROR(VLOOKUP(A10,القائمة!$A$3:$F$112,4,FALSE),"") | E10: =IFERROR(VLOOKUP(A10,القائمة!$A$3:$F$112,5,FALSE),"") | F10: =IFERROR(VLOOKUP(A10,القائمة!$A$3:$F$112,6,FALSE),"") | P10: =J10-K10 -> 0 | Q10: =+P10+L10-M10 -> 0
B11: =IFERROR(VLOOKUP(A11,القائمة!$A$3:$F$112,2,FALSE),"") | C11: =IFERROR(VLOOKUP(A11,القائمة!$A$3:$F$112,3,FALSE),"") | D11: =IFERROR(VLOOKUP(A11,القائمة!$A$3:$F$112,4,FALSE),"") | E11: =IFERROR(VLOOKUP(A11,القائمة!$A$3:$F$112,5,FALSE),"") | F11: =IFERROR(VLOOKUP(A11,القائمة!$A$3:$F$112,6,FALSE),"") | P11: =J11-K11 -> 0 | Q11: =+P11+L11-M11 -> 0
B12: =IFERROR(VLOOKUP(A12,القائمة!$A$3:$F$112,2,FALSE),"") | C12: =IFERROR(VLOOKUP(A12,القائمة!$A$3:$F$112,3,FALSE),"") | D12: =IFERROR(VLOOKUP(A12,القائمة!$A$3:$F$112,4,FALSE),"") | E12: =IFERROR(VLOOKUP(A12,القائمة!$A$3:$F$112,5,FALSE),"") | F12: =IFERROR(VLOOKUP(A12,القائمة!$A$3:$F$112,6,FALSE),"") | P12: =J12-K12 -> 0 | Q12: =+P12+L12-M12 -> 0
B13: =IFERROR(VLOOKUP(A13,القائمة!$A$3:$F$112,2,FALSE),"") | C13: =IFERROR(VLOOKUP(A13,القائمة!$A$3:$F$112,3,FALSE),"") | D13: =IFERROR(VLOOKUP(A13,القائمة!$A$3:$F$112,4,FALSE),"") | E13: =IFERROR(VLOOKUP(A13,القائمة!$A$3:$F$112,5,FALSE),"") | F13: =IFERROR(VLOOKUP(A13,القائمة!$A$3:$F$112,6,FALSE),"") | P13: =J13-K13 -> 0 | Q13: =+P13+L13-M13 -> 0
B14: =IFERROR(VLOOKUP(A14,القائمة!$A$3:$F$112,2,FALSE),"") | C14: =IFERROR(VLOOKUP(A14,القائمة!$A$3:$F$112,3,FALSE),"") | D14: =IFERROR(VLOOKUP(A14,القائمة!$A$3:$F$112,4,FALSE),"") | E14: =IFERROR(VLOOKUP(A14,القائمة!$A$3:$F$112,5,FALSE),"") | F14: =IFERROR(VLOOKUP(A14,القائمة!$A$3:$F$112,6,FALSE),"") | P14: =J14-K14 -> 0 | Q14: =+P14+L14-M14 -> 0
... B2001: =IFERROR(VLOOKUP(A2001,القائمة!$A$3:$F$112,2,FALSE),"") | C2001: =IFERROR(VLOOKUP(A2001,القائمة!$A$3:$F$112,3,FALSE),"") | D2001: =IFERROR(VLOOKUP(A2001,القائمة!$A$3:$F$112,4,FALSE),"") | E2001: =IFERROR(VLOOKUP(A2001,القائمة!$A$3:$F$112,5,FALSE),"") | F2001: =IFERROR(VLOOKUP(A2001,القائمة!$A$3:$F$112,6,FALSE),"") | P2001: =J2001-K2001 -> 0 | Q2001: =+P2001+L2001-M2001 -> 0

Sheet التحليل
A1: - | B1: التبويب العام الحالى | C1: التصنيف الرئيسى العام الحالى | D1: الكود | E1: اسم الحساب | F1: رصيد اخر | G1: رصيد اول | H1: مدين اخر | I1: دائن اخر | J1: حركة مدينة | K1: حركة دائنة | L1: مدين اول | M1: دائن اول
A2: 1 | B2: النقدية ومافي حكمها | C2: البنوك | F2: 874353.06 | G2: 974832.45 | H2: 874353.06 | J2: 19589621 | K2: 19690100
C3: الصندوق | F3: 3636.29 | G3: 0 | H3: 3636.29 | J3: 220700 | K3: 217063.71
B4: النقدية ومافي حكمها الإجمالي | F4: 877989.35 | G4: 974832.45 | H4: 877989.35 | J4: 19810321 | K4: 19907164
A5: 2 | B5: الذمم المدينة | C5: ذمم العملاء | F5: 3182524.6 | G5: 3472424.7 | H5: 3182524.6 | J5: 15717003 | K5: 16006904
B6: الذمم المدينة الإجمالي | F6: 3182524.6 | G6: 3472424.7 | H6: 3182524.6 | J6: 15717003 | K6: 16006904
A7: 3 | B7: أرصدة مدينة أخري | C7: المصروفات المدفوعة مقدماً | F7: 917596.15 | G7: 1016976.2 | H7: 917596.15 | J7: 598541.8 | K7: 697921.89
C8: ذمم العاملين | F8: 47247 | G8: 16349 | H8: 47247 | J8: 183818.5 | K8: 152920.5
C9: خطابات الضمان | F9: 0 | G9: 0 | H9: 0 | J9: 3237200 | K9: 3237200
C10: عهد عاملين | F10: -52144.45 | G10: -35618.75 | H10: -52144.45 | J10: 1905039.8 | K10: 1921565.5
B11: أرصدة مدينة أخري الإجمالي | F11: 912698.7 | G11: 997706.49 | H11: 912698.7 | J11: 5924600.1 | K11: 6009607.9
A12: 6 | B12: عقارات والات و معدات (بالصافى) | C12: أثاث ومفروشات | F12: 19483.67 | G12: 22302.24 | H12: 19483.67 | J12: 0 | K12: 2818.57
C13: سيارات | F13: 676869.71 | G13: 341256.86 | H13: 676869.71 | J13: 635855.22 | K13: 300242.37
C14: معدات مكتبية | F14: 34583.16 | G14: 38742.7 | H14: 34583.16 | J14: 14759.88 | K14: 18919.42
C15: عدد و ادوات | F15: 90285.31 | G15: 110000 | H15: 90285.31 | J15: 9210.71 | K15: 28925.4
B16: عقارات والات و معدات (بالصافى) الإجمالي | F16: 821221.85 | G16: 512301.8 | H16: 821221.85 | J16: 659825.81 | K16: 350905.76
A17: 12 | B17: الذمم الدائنة | C17: ذمم الموردين | F17: -2831768.2 | G17: -1893227.3 | H17: -2831768.2 | J17: 3738636.6 | K17: 4677177.6
B18: الذمم الدائنة الإجمالي | F18: -2831768.2 | G18: -1893227.3 | H18: -2831768.2 | J18: 3738636.6 | K18: 4677177.6
A19: 13 | B19: ارصدة دائنة اخرى | C19: المصروفات المستحقة | F19: -860791.39 | G19: -528482 | H19: -860791.39 | J19: 6838053.4 | K19: 7170362.8
C20: ضريبة القيمة المضافة | F20: -477733.51 | G20: -823073.18 | H20: -477733.51 | J20: 2397333.7 | K20: 2051994
B21: ارصدة دائنة اخرى الإجمالي | F21: -1338524.9 | G21: -1351555.2 | H21: -1338524.9 | J21: 9235387.1 | K21: 9222356.8
A22: 17 | B22: مخصص الزكاة الشرعية والضريبة | C22: مخصص الزكاة الشرعية | F22: -96081 | G22: -105349 | H22: -96081 | J22: 105349 | K22: 96081
B23: مخصص الزكاة الشرعية والضريبة الإجمالي | F23: -96081 | G23: -105349 | H23: -96081 | J23: 105349 | K23: 96081
A24: 19 | B24: مخصص مكافأة نهاية الخدمة | C24: مخصص مكافأة نهاية الخدمة | F24: -334861.58 | G24: -271750.74 | H24: -334861.58 | J24: 51006.84 | K24: 114117.68
B25: مخصص مكافأة نهاية الخدمة الإجمالي | F25: -334861.58 | G25: -271750.74 | H25: -334861.58 | J25: 51006.84 | K25: 114117.68
A26: 20 | B26: أطراف ذات علاقة | C26: أطراف ذات علاقة دائنة | F26: 2745136.6 | G26: 1829098.9 | H26: 2745136.6 | J26: 2428734.5 | K26: 1512696.8
B27: أطراف ذات علاقة الإجمالي | F27: 2745136.6 | G27: 1829098.9 | H27: 2745136.6 | J27: 2428734.5 | K27: 1512696.8
A28: 21 | B28: راس المال | C28: راس المال | F28: -100000 | G28: -70000 | H28: -100000 | J28: 20000 | K28: 50000
B29: راس المال الإجمالي | F29: -100000 | G29: -70000 | H29: -100000 | J29: 20000 | K29: 50000
A30: 24 | B30: الارباح المبقاه | C30: الارباح المبقاه | F30: -4094482.1 | G30: -4094482.1 | H30: -4094482.1 | J30: 0 | K30: 0
B31: الارباح المبقاه الإجمالي | F31: -4094482.1 | G31: -4094482.1 | H31: -4094482.1 | J31: 0 | K31: 0
A32: 25 | B32: الايرادات | C32: اجمالى الايرادات | F32: -13178071 | G32: 0 | H32: -13178071 | J32: 488888.88 | K32: 13666960
C33: خصم مسموح به | D33: 42000 | E33: ايرادات اخري | F33: -21104.65 | G33: 0 | H33: -21104.65 | J33: 0 | K33: 21104.65
C34: خصم مسموح به الإجمالي | F34: -21104.65 | G34: 0 | H34: -21104.65 | J34: 0 | K34: 21104.65
B35: الايرادات الإجمالي | F35: -13199175 | G35: 0 | H35: -13199175 | J35: 488888.88 | K35: 13688064
A36: 26 | B36: تكلفة الايرادات | C36: مصاريف التشغيل | F36: 843680.65 | G36: 0 | H36: 843680.65 | J36: 846608.15 | K36: 2927.5
C37: المشتريات | F37: 2476506.7 | G37: 0 | H37: 2476506.7 | J37: 2476506.7 | K37: 0
B38: تكلفة الايرادات الإجمالي | F38: 3320187.4 | G38: 0 | H38: 3320187.4 | J38: 3323114.9 | K38: 2927.5
A39: 28 | B39: المصروفات العمومية والادارية | C39: المصروفات العمومية والادارية | F39: 10036216 | G39: 0 | H39: 10036216 | J39: 10080092 | K39: 43876.23
B40: المصروفات العمومية والادارية الإجمالي | F40: 10036216 | G40: 0 | H40: 10036216 | J40: 10080092 | K40: 43876.23
...

Sheet التحليل (دخل)
A1: القائمة | B1: دخل
A3: - | B3: التبويب العام الحالى | C3: التصنيف الرئيسى العام الحالى | D3: CODE | E3: التصنيف الفرعى العام الحالى | F3: الكود | G3: اسم الحساب | H3: رصيد اخر | I3: حركة مدينة | J3: حركة دائنة | K3: مدين اخر | L3: دائن اخر
A4: 25 | B4: الايرادات | C4: اجمالى الايرادات | H4: -13178071 | I4: 488888.88 | J4: 13666960 | K4: -13178071
C5: خصم مسموح به | D5: 2502 | E5: 0 | H5: -21104.65 | I5: 0 | J5: 21104.65 | K5: -21104.65
C6: خصم مسموح به الإجمالي | H6: -21104.65 | I6: 0 | J6: 21104.65 | K6: -21104.65
B7: الايرادات الإجمالي | H7: -13199175 | I7: 488888.88 | J7: 13688064 | K7: -13199175
A8: 26 | B8: تكلفة الايرادات | C8: مصاريف التشغيل | D8: 2608 | E8: سفر ونقل وانتقالات | H8: 179580.12 | I8: 179620.12 | J8: 40 | K8: 179580.12
D9: 2613 | E9: قرطاسية ومطبوعات | H9: 1400 | I9: 1400 | J9: 0 | K9: 1400
D10: 2615 | E10: زيوت ومحروقات | H10: 43802.33 | I10: 43802.33 | J10: 0 | K10: 43802.33
D11: 2616 | E11: صيانة وإصلاح | H11: 21132.02 | I11: 21132.02 | J11: 0 | K11: 21132.02
D12: 2620 | E12: مصاريف متنوعة | H12: 597766.18 | I12: 600653.68 | J12: 2887.5 | K12: 597766.18
C13: مصاريف التشغيل الإجمالي | H13: 843680.65 | I13: 846608.15 | J13: 2927.5 | K13: 843680.65
C14: المشتريات | H14: 2476506.7 | I14: 2476506.7 | J14: 0 | K14: 2476506.7
B15: تكلفة الايرادات الإجمالي | H15: 3320187.4 | I15: 3323114.9 | J15: 2927.5 | K15: 3320187.4
A16: 28 | B16: المصروفات العمومية والادارية | C16: المصروفات العمومية والادارية | D16: 2801 | E16: رواتب وأجور وما في حكمها | H16: 7591721.9 | I16: 7591721.9 | J16: 0 | K16: 7591721.9
D17: 2802 | E17: تأمينات إجتماعية | H17: 419930.69 | I17: 419930.69 | J17: 0 | K17: 419930.69
D18: 2803 | E18: تأمين طبي وعلاج | H18: 318349.22 | I18: 346530.65 | J18: 28181.43 | K18: 318349.22
D19: 2804 | E19: سفر ونقل وانتقالات | H19: 6803 | I19: 6803 | J19: 0 | K19: 6803
D20: 2805 | E20: مكافأة نهاية الخدمة | H20: 114117.68 | I20: 114117.68 | J20: 0 | K20: 114117.68
D21: 2806 | E21: الإنخفاض في قيمة الذمم | H21: 63190.65 | I21: 63190.65 | J21: 0 | K21: 63190.65
D22: 2807 | E22: الإيجارات | H22: 203270.26 | I22: 203270.26 | J22: 0 | K22: 203270.26
D23: 2808 | E23: رسوم حكومية واشتراكات | H23: 834944.7 | I23: 839670.7 | J23: 4726 | K23: 834944.7
D24: 2809 | E24: كهرباء ومياه و مرافق | H24: 30351.04 | I24: 30351.04 | J24: 0 | K24: 30351.04
D25: 2810 | E25: قرطاسية ومطبوعات | H25: 23784.19 | I25: 23784.19 | J25: 0 | K25: 23784.19
D26: 2811 | E26: بريد وهاتف وانترنت | H26: 28413.29 | I26: 29848.74 | J26: 1435.45 | K26: 28413.29
D27: 2815 | E27: أتعاب مهنية واستشارات | H27: 19999.56 | I27: 19999.56 | J27: 0 | K27: 19999.56
D28: 2816 | E28: عمولات ومكافآت | H28: 173863.82 | I28: 173863.82 | J28: 0 | K28: 173863.82
... D31: 2819 | E31: مصاريف متنوعة | H31: 108821.09 | I31: 117821.09 | J31: 9000 | K31: 108821.09
C32: المصروفات العمومية والادارية الإجمالي | H32: 10036216 | I32: 10080092 | J32: 43876.23 | K32: 10036216
B33: المصروفات العمومية والادارية الإجمالي | H33: 10036216 | I33: 10080092 | J33: 43876.23 | K33: 10036216
A34: 30 | B34: استهلاك العقارات والآلات والمعدات | C34: استهلاك العقارات والآلات والمعدات | H34: 98918.98 | I34: 139005.76 | J34: 40086.78 | K34: 98918.98
B35: استهلاك العقارات والآلات والمعدات الإجمالي | H35: 98918.98 | I35: 139005.76 | J35: 40086.78 | K35: 98918.98
A36: الإجمالي الكلي | H36: 256146.78 | I36: 14031101 | J36: 13774955 | K36: 256146.78

Sheet ميزان فرعى
A1: - | B1: ذمم العملاء
A3: - | B3: اسم الحساب | C3: مدين اول | D3: دائن اول | E3: حركة مدينة | F3: حركة دائنة | G3: مدين اخر | H3: دائن اخر | I3: رصيد اخر | J3: رصيد اول
A4: 12000 | B4: حسابات العملاء | E4: 15717003 | F4: 16006904 | G4: 3182524.6 | I4: 3182524.6 | J4: 3472424.7
A5: الاجمالى | E5: 15717003 | F5: 16006904 | G5: 3182524.6 | I5: 3182524.6 | J5: 3472424.7
N30: 75027
N31: 7876921

Sheet ميزان فرعى (دخل)
A1: - | B1: المصروفات العمومية والادارية
A3: - | B3: التصنيف الفرعى العام الحالى | C3: الكود | D3: اسم الحساب | E3: مدين اول | F3: دائن اول | G3: حركة مدينة | H3: حركة دائنة | I3: مدين اخر | J3: دائن اخر | K3: رصيد اخر | L3: رصيد اول
A4: 2801 | B4: رواتب وأجور وما في حكمها | C4: 61001001 | D4: الراتب الاساسي | G4: 3199796.8 | H4: 0 | I4: 3199796.8 | K4: 3199796.8 | L4: 0
C5: 61001003 | D5: بدل السكن | G5: 818000 | H5: 0 | I5: 818000 | K5: 818000 | L5: 0
C6: 61001004 | D6: بدلات اخري | G6: 3166783.1 | H6: 0 | I6: 3166783.1 | K6: 3166783.1 | L6: 0
C7: 61001010 | D7: م اجور ورواتب عمالة خارجية وما في حكمها | G7: 407142 | H7: 0 | I7: 407142 | K7: 407142 | L7: 0
B8: رواتب وأجور وما في حكمها Total | G8: 7591721.9 | H8: 0 | I8: 7591721.9 | K8: 7591721.9 | L8: 0
A9: 2802 | B9: تأمينات إجتماعية | C9: 61001005 | D9: م التامينات الاجتماعية | G9: 419930.69 | H9: 0 | I9: 419930.69 | K9: 419930.69 | L9: 0
B10: تأمينات إجتماعية Total | G10: 419930.69 | H10: 0 | I10: 419930.69 | K10: 419930.69 | L10: 0
A11: 2803 | B11: تأمين طبي وعلاج | C11: 61001011 | D11: م التامين الطبي للموظفين | G11: 330935.92 | H11: 28181.43 | I11: 302754.49 | K11: 302754.49 | L11: 0
C12: 62001016 | D12: مصروف تأمين | G12: 15594.73 | H12: 0 | I12: 15594.73 | K12: 15594.73 | L12: 0
B13: تأمين طبي وعلاج Total | G13: 346530.65 | H13: 28181.43 | I13: 318349.22 | K13: 318349.22 | L13: 0
A14: 2804 | B14: سفر ونقل وانتقالات | C14: 62001013 | D14: م الخروج والعوده | G14: 6803 | H14: 0 | I14: 6803 | K14: 6803 | L14: 0
B15: سفر ونقل وانتقالات Total | G15: 6803 | H15: 0 | I15: 6803 | K15: 6803 | L15: 0
A16: 2808 | B16: رسوم حكومية واشتراكات | C16: 62001007 | D16: م تجديد الاقامات وملحقاتها | G16: 520045 | H16: 4726 | I16: 515319 | K16: 515319 | L16: 0
C17: 62001008 | D17: مصروفات تدريب ودورات | G17: 42734 | H17: 0 | I17: 42734 | K17: 42734 | L17: 0
C18: 62001009 | D18: م اشتراكات ومواقع انترنت | G18: 235119.34 | H18: 0 | I18: 235119.34 | K18: 235119.34 | L18: 0
C19: 64001003 | D19: رسوم غرفة تجارية | G19: 1120 | H19: 0 | I19: 1120 | K19: 1120 | L19: 0
C20: 64001007 | D20: مصروفات ورسوم حكومية | G20: 40652.36 | H20: 0 | I20: 40652.36 | K20: 40652.36 | L20: 0
B21: رسوم حكومية واشتراكات Total | G21: 839670.7 | H21: 4726 | I21: 834944.7 | K21: 834944.7 | L21: 0
A22: 2810 | B22: قرطاسية ومطبوعات | C22: 62001003 | D22: م شراء مستلزمات كومبيوتر | G22: 15400.1 | H22: 0 | I22: 15400.1 | K22: 15400.1 | L22: 0
C23: 62001010 | D23: م مكتبية وقرطاسية ومطبوعات | G23: 8384.09 | H23: 0 | I23: 8384.09 | K23: 8384.09 | L23: 0
B24: قرطاسية ومطبوعات Total | G24: 23784.19 | H24: 0 | I24: 23784.19 | K24: 23784.19 | L24: 0
A25: 2811 | B25: بريد وهاتف وانترنت | C25: 64001002 | D25: مصروفات البريد والمراسلات | G25: 3126.61 | H25: 0 | I25: 3126.61 | K25: 3126.61 | L25: 0
C26: 64001004 | D26: م هاتف وانترنت المكتب | G26: 26722.13 | H26: 1435.45 | I26: 25286.68 | K26: 25286.68 | L26: 0
B27: بريد وهاتف وانترنت Total | G27: 29848.74 | H27: 1435.45 | I27: 28413.29 | K27: 28413.29 | L27: 0
A28: 2815 | B28: أتعاب مهنية واستشارات | C28: 62001006 | D28: مصروفات مهنية (محاسبة ومراجعة) | G28: 19999.56 | H28: 0 | I28: 19999.56 | K28: 19999.56 | L28: 0
B29: أتعاب مهنية واستشارات Total | G29: 19999.56 | H29: 0 | I29: 19999.56 | K29: 19999.56 | L29: 0
A30: 2817 | B30: ضيافة ونظافة | C30: 62001001 | D30: م ضيافة واعاشة | G30: 57079.81 | H30: 0 | I30: 57079.81 | K30: 57079.81 | L30: 0 | N30: 75027
C31: 62001002 | D31: م نظافة للمكتب | G31: 7214.74 | H31: 0 | I31: 7214.74 | K31: 7214.74 | L31: 0 | N31: 7876921
B32: ضيافة ونظافة Total | G32: 64294.55 | H32: 0 | I32: 64294.55 | K32: 64294.55 | L32: 0
A33: 2818 | B33: عمولات و رسوم بنكية | C33: 62001005 | D33: مصروفات وعمولات بنكية | G33: 34893.43 | H33: 533.35 | I33: 34360.08 | K33: 34360.08 | L33: 0
B34: عمولات و رسوم بنكية Total | G34: 34893.43 | H34: 533.35 | I34: 34360.08 | K34: 34360.08 | L34: 0
A35: 2819 | B35: مصاريف متنوعة | C35: 62001011 | D35: م مستلزمات سكن موظفين | G35: 22180.12 | H35: 0 | I35: 22180.12 | K35: 22180.12 | L35: 0
C36: 62001017 | D36: مصروف فوائد تأجير تمويلى | G36: 17838.7 | H36: 0 | I36: 17838.7 | K36: 17838.7 | L36: 0
C37: 62001018 | D37: م تمويل | G37: 69000 | H37: 9000 | I37: 60000 | K37: 60000 | L37: 0
C38: 64001012 | D38: رسوم ادارية | G38: 8802.27 | H38: 0 | I38: 8802.27 | K38: 8802.27 | L38: 0
B39: مصاريف متنوعة Total | G39: 117821.09 | H39: 9000 | I39: 108821.09 | K39: 108821.09 | L39: 0
A40: 2809 | B40: كهرباء ومياه و مرافق | C40: 64001001 | D40: م كهرباء -مياه | G40: 30351.04 | H40: 0 | I40: 30351.04 | K40: 30351.04 | L40: 0
B41: كهرباء ومياه و مرافق Total | G41: 30351.04 | H41: 0 | I41: 30351.04 | K41: 30351.04 | L41: 0
...

Sheet ق م
B1: مبيعات محلية | I1: =+G15+G30 -> 0
B2: 0.05 | D2: 0.15 | F2: معفاه
A3: 1 | C3: =ROUND(+B3*0.05,2) -> 0 | E3: =ROUND(+D3*0.15,2) -> 0 | G3: =+B3+D3+F3 -> 0 | H3: =+C3+E3 -> 0 | I3: =+G3+G18 -> 0
A4: 2 | C4: =ROUND(+B4*0.05,2) -> 0 | E4: =ROUND(+D4*0.15,2) -> 0 | G4: =+B4+D4+F4 -> 0 | H4: =+C4+E4 -> 0 | I4: =+G4+G19 -> 0
A5: 3 | C5: =ROUND(+B5*0.05,2) -> 0 | E5: =ROUND(+D5*0.15,2) -> 0 | G5: =+B5+D5+F5 -> 0 | H5: =+C5+E5 -> 0 | I5: =+G5+G20 -> 0
A6: 4 | C6: =ROUND(+B6*0.05,2) -> 0 | E6: =ROUND(+D6*0.15,2) -> 0 | G6: =+B6+D6+F6 -> 0 | H6: =+C6+E6 -> 0 | I6: =+G6+G21 -> 0
A7: 5 | C7: =ROUND(+B7*0.05,2) -> 0 | E7: =ROUND(+D7*0.15,2) -> 0 | G7: =+B7+D7+F7 -> 0 | H7: =+C7+E7 -> 0 | I7: =+G7+G22 -> 0
A8: 6 | C8: =ROUND(+B8*0.05,2) -> 0 | E8: =ROUND(+D8*0.15,2) -> 0 | G8: =+B8+D8+F8 -> 0 | H8: =+C8+E8 -> 0 | I8: =+G8+G23 -> 0
A9: 7 | C9: =ROUND(+B9*0.05,2) -> 0 | E9: =ROUND(+D9*0.15,2) -> 0 | G9: =+B9+D9+F9 -> 0 | H9: =+C9+E9 -> 0 | I9: =+G9+G24 -> 0
A10: 8 | C10: =ROUND(+B10*0.05,2) -> 0 | E10: =ROUND(+D10*0.15,2) -> 0 | G10: =+B10+D10+F10 -> 0 | H10: =+C10+E10 -> 0 | I10: =+G10+G25 -> 0
A11: 9 | C11: =ROUND(+B11*0.05,2) -> 0 | E11: =ROUND(+D11*0.15,2) -> 0 | G11: =+B11+D11+F11 -> 0 | H11: =+C11+E11 -> 0 | I11: =+G11+G26 -> 0
A12: 10 | C12: =ROUND(+B12*0.05,2) -> 0 | E12: =ROUND(+D12*0.15,2) -> 0 | G12: =+B12+D12+F12 -> 0 | H12: =+C12+E12 -> 0 | I12: =+G12+G27 -> 0
A13: 11 | C13: =ROUND(+B13*0.05,2) -> 0 | E13: =ROUND(+D13*0.15,2) -> 0 | G13: =+B13+D13+F13 -> 0 | H13: =+C13+E13 -> 0 | I13: =+G13+G28 -> 0
A14: 12 | C14: =ROUND(+B14*0.05,2) -> 0 | E14: =ROUND(+D14*0.15,2) -> 0 | G14: =+B14+D14+F14 -> 0 | H14: =+C14+E14 -> 0 | I14: =+G14+G29 -> 0
G15: =SUM(G3:G14) -> 0
B16: صادرات
A18: 1 | G18: =+B18+D18+F18 -> 0
A19: 2 | G19: =+B19+D19+F19 -> 0
A20: 3 | G20: =+B20+D20+F20 -> 0
A21: 4 | G21: =+B21+D21+F21 -> 0
A22: 5 | G22: =+B22+D22+F22 -> 0
A23: 6 | G23: =+B23+D23+F23 -> 0
A24: 7 | G24: =+B24+D24+F24 -> 0
A25: 8 | G25: =+B25+D25+F25 -> 0
A26: 9 | G26: =+B26+D26+F26 -> 0
A27: 10 | G27: =+B27+D27+F27 -> 0
A28: 11 | G28: =+B28+D28+F28 -> 0
A29: 12 | G29: =+B29+D29+F29 -> 0
G30: =SUM(G18:G29) -> 0
B32: مشتريات محلية
B33: 0.05 | D33: 0.15 | F33: معفاه | I33: =G46+G61 -> 0
A34: 1 | C34: =ROUND(+B34*0.05,2) -> 0 | E34: =ROUND(+D34*0.15,2) -> 0 | G34: =+B34+D34+F34 -> 0 | H34: =+C34+E34 -> 0 | I34: =+G34+G49 -> 0
A35: 2 | C35: =ROUND(+B35*0.05,2) -> 0 | E35: =ROUND(+D35*0.15,2) -> 0 | G35: =+B35+D35+F35 -> 0 | H35: =+C35+E35 -> 0 | I35: =+G35+G50 -> 0
A36: 3 | C36: =ROUND(+B36*0.05,2) -> 0 | E36: =ROUND(+D36*0.15,2) -> 0 | G36: =+B36+D36+F36 -> 0 | H36: =+C36+E36 -> 0 | I36: =+G36+G51 -> 0
A37: 4 | C37: =ROUND(+B37*0.05,2) -> 0 | E37: =ROUND(+D37*0.15,2) -> 0 | G37: =+B37+D37+F37 -> 0 | H37: =+C37+E37 -> 0 | I37: =+G37+G52 -> 0
A38: 5 | C38: =ROUND(+B38*0.05,2) -> 0 | E38: =ROUND(+D38*0.15,2) -> 0 | G38: =+B38+D38+F38 -> 0 | H38: =+C38+E38 -> 0 | I38: =+G38+G53 -> 0
A39: 6 | C39: =ROUND(+B39*0.05,2) -> 0 | E39: =ROUND(+D39*0.15,2) -> 0 | G39: =+B39+D39+F39 -> 0 | H39: =+C39+E39 -> 0 | I39: =+G39+G54 -> 0
A40: 7 | C40: =ROUND(+B40*0.05,2) -> 0 | E40: =ROUND(+D40*0.15,2) -> 0 | G40: =+B40+D40+F40 -> 0 | H40: =+C40+E40 -> 0 | I40: =+G40+G55 -> 0
A41: 8 | C41: =ROUND(+B41*0.05,2) -> 0 | E41: =ROUND(+D41*0.15,2) -> 0 | G41: =+B41+D41+F41 -> 0 | H41: =+C41+E41 -> 0 | I41: =+G41+G56 -> 0
A42: 9 | C42: =ROUND(+B42*0.05,2) -> 0 | E42: =ROUND(+D42*0.15,2) -> 0 | G42: =+B42+D42+F42 -> 0 | H42: =+C42+E42 -> 0 | I42: =+G42+G57 -> 0
...
