Workbook
Name \: #REF!
Name \0: #REF!
Name \0: #REF!
Name \0: #REF!
Name \a: #REF!
Name \a: #REF!
Name \a: #REF!
Name \b: #REF!
Name \b: #REF!
Name \b: #REF!
Name _1E____ဠ0__큌〈Ř: #REF!
Name _1E____ဠ0__큌〈Ř: #REF!
Name _1E____ဠ0__큌〈Ř: #REF!
Name _aay135: '[2]0440'!$AY$8
Name _adj1: [3]testing!#REF!
Name _adj1: [3]testing!#REF!
Name _adj1: [3]testing!#REF!
Name _Col1: #REF!
Name _Col1: #REF!
Name _Col1: #REF!
Name _DAT1: #REF!
Name _DAT10: #REF!
Name _DAT11: #REF!
Name _DAT12: #REF!
Name _DAT13: #REF!
Name _DAT14: #REF!
Name _DAT15: #REF!
Name _DAT16: #REF!
Name _DAT17: #REF!
Name _DAT18: #REF!
Name _DAT19: #REF!
Name _DAT2: #REF!
Name _DAT20: #REF!
Name _DAT21: #REF!
Name _DAT22: #REF!
Name _DAT23: #REF!
Name _DAT24: #REF!
Name _DAT3: #REF!
Name _DAT4: #REF!
Name _DAT5: #REF!
Name _DAT6: #REF!
Name _DAT7: #REF!
Name _DAT8: #REF!
Name _DAT9: [4]Additions!#REF!
Name _DAT9: [4]Additions!#REF!
Name _DAT9: [4]Additions!#REF!
Name _feb04: #REF!
Name _MOD5: #REF!
Name _pg1: #REF!
Name _pg1: #REF!
Name _pg1: #REF!
Name _pg2: #REF!
Name _pg2: #REF!
Name _pg2: #REF!
Name _PR1: #REF!
Name _PR1: #REF!
Name _PR1: #REF!
Name _PR10: #REF!
Name _PR10: #REF!
Name _PR10: #REF!

Sheet K1 New
A2: Kingdom of Saudi Arabia | M2: Form No (K1 Accounts)
A3: Ministry of Finance
A4: Zakat ,Tax and Customs Authority (ZATCA)
A8: Branch: Jeddah | D8: Tax / Zakat Return for all Tax / Zakat payers filing based on statutory records | M8: Unique No. ***********
A11: BASIC INFORMATION
B12: Commercial Name | M12: Financial Year
B14: Legal Status | D14: Saudi / GCC Share | E14: 1 | G14: Non-Saudi Share | J14: =100%-E14 -> 0 | M14: From: 01 / 01 / 2024
M15: To: 31 / 12 / 2024
D17: Share of profit from Saudi | E17: =E14 -> 1 | G17: Share of profit from non-Saudi | J17: =100%-E17 -> 0 | M17: (For ZATCA use only)
B19: Main Activity | M19: Code: | N19: _______________
B22: Description of the Main Activity | D22: =D19 -> 0 | M22: Document Location No. | N22: _______________
B25: Address | D25: P.O. Box | E25: Zip Code | G25: Tel | J25: Fax | L25: E-mail
B28: Location | D28: Building | G28: Street | J28: District | N28: City
A30: Sr. No. | N30: Saudi Riyals
A31: ZAKAT COMPUTATION
A32: Net adjusted Profit | C32: 10000 | D32: Net Profit/(Loss) as per the books | N32: 0
C33: 10001 | D33: Adjustments to the Net Profit For Saudi Shareholding - (Statement 1) | N33: ='ST 1 - Adjustments to NP'!D34 -> 0
C34: 10002 | D34: Adjusted profit/(Loss) related to Saudi shareholding in the profit / (loss) | M34: 1 | N34: =N32+'ST 1 - Adjustments to NP'!E34 -> 0
A35: Additions to the Zakat Base (Article 23)
A36: ADDITIONS | C36: 10003 | D36: Equity & Reserves - (Statement 2) | I36: Applicable | K36: Not Applicable | M36: ='ST 2 - Equity'!D21 -> 0
C37: 10004 | D37: Liabilities & Other additions to the Zakat Base - (Statement -3) | I37: Applicable | K37: Not Applicable | M37: ='ST 3 - Liabilities'!E24 -> 0
C38: 10005 | D38: Total Zakat adjustments | M38: ='ST 1 - Adjustments to NP'!E34 -> 0
A39: 10006 | C39: Total additions (sum of 10008 to 10010) | N39: =SUM(M36:M38) -> 0
A40: Deductions from the Zakat Base
A41: DEDUCTIONS (11300) | C41: 10007 | D41: Net fixed assets and their equivalents - (Statement - 4) | I41: Applicable | K41: Not Applicable | M41: ='ST 4 - Fixed Assets & related'!D20 -> 0
C42: 10008 | D42: Investments - (Statement - 5) | I42: Applicable | K42: Not Applicable | M42: ='ST 5 - Investments'!D16 -> 0
C43: 10009 | D43: Real estate and projects under development for sale - (Statement - 6) | I43: Applicable | K43: Not Applicable | M43: ='ST 6 - Properties under develop'!C18 -> 0
C44: 10010 | D44: Other Deductions - (Statement - 7) | I44: Applicable | K44: Not Applicable | M44: ='ST 7 - Other deductions'!C16 -> 0
A45: 10011 | C45: Total deductions (sum of 10013 to 10016) | N45: =SUM(M41:M44) -> 0
A46: 10012 | C46: Total Zakat Base (Total Additions - Total Deductions) | N46: =N39-N45 -> 0
A47: Minumum Zakat Base (Article 27)
A48: 10013 | C48: Total assets according to the statement of financial position - (Non - Current Assets + Current Assets) | M48: ='ST 8 -Total assets'!B16 -> 0
A49: 10014 | C49: Undeductible Assets (Total Assets 10019 - Total Deductions 10017) | M49: =M48-N45 -> 0
A50: 10015 | C50: The difference between net book profit and adjusted profit | M50: ='ST 1 - Adjustments to NP'!E34 -> 0
A51: 10016 | C51: Total Minumum Zakat base - (Minimum of Non-deductible assets plus adjustment to the net profit) and (Net Adjusted profit) | N51: =MIN((M49+M50),N34) -> 0
A52: Maximum Zakat Base (Article 28)
A53: 10019 | C53: Equity and the like according to the statement of financial position and any item reclassified to become equity | M53: =M36 -> 0
A54: 10020 | C54: The difference between net book profit and adjusted profit - [Zakat Regulation refernce - 23(3)] | M54: ='ST 1 - Adjustments to NP'!E34 -> 0
A55: 10021 | C55: Total Maximum zakat base - (Equity (and equivalent) plus adjustment to the net profit (positive or negative) | N55: =SUM(M53:M54) -> 0
A56: Zakat Base (10020) & Zakat Liability
...

Sheet ST 1 - Adjustments to NP
A1: Zakat/Tax payer's Name:
A2: Unique No :
A3: Year ended :
A6: Statement 1 : Adjustments to the Net Profit
A7: Sr. No | B7: Description | C7: Type | D7: Amount | E7: Zakat Share | F7: Tax Share
A8: 1 | B8: Salaries, fees and the like paid to owners, partners, shareholders and their irregular relatives | C8: Mixed | D8: 0 | E8: =D8*'K1 New'!$E$14 -> 0 | F8: =D8*'K1 New'!$J$14 -> 0
A9: =A8+1 -> 2 | B9: (Royals/financial fees/loan returns/indirect expenses charged using the estimated method) for the head office | C9: Tax | D9: 0 | E9: =D9*'K1 New'!$E$14 -> 0 | F9: =D9*'K1 New'!$J$14 -> 0
A10: =A9+1 -> 3 | B10: Social insurance paid abroad | C10: Tax | D10: 0 | E10: =D10*'K1 New'!$E$14 -> 0 | F10: =D10*'K1 New'!$J$14 -> 0
A11: =A10+1 -> 4 | B11: Employer contributions to statutory retirement funds in excess of the statutory percentage | C11: Mixed | D11: 0 | E11: =D11*'K1 New'!$E$14 -> 0 | F11: =D11*'K1 New'!$J$14 -> 0
A12: =A11+1 -> 5 | B12: Entertainment expenses | C12: Tax | D12: 0 | E12: =D12*'K1 New'!$E$14 -> 0 | F12: =D12*'K1 New'!$J$14 -> 0
A13: =A12+1 -> 6 | B13: School fees for children of irregular employees | C13: Mixed | D13: 0 | E13: =D13*'K1 New'!$E$14 -> 0 | F13: =D13*'K1 New'!$J$14 -> 0
A14: =A13+1 -> 7 | B14: Irregular fines and penalties | C14: Tax | D14: 0 | E14: =D14*'K1 New'!$E$14 -> 0 | F14: =D14*'K1 New'!$J$14 -> 0
A15: =A14+1 -> 8 | B15: Capital losses (gains) from the sale of assets | C15: Tax | D15: 0 | E15: =D15*'K1 New'!$E$14 -> 0 | F15: =D15*'K1 New'!$J$14 -> 0
A16: =A15+1 -> 9 | B16: Donations not permitted | C16: Mixed | E16: =D16*'K1 New'!$E$14 -> 0 | F16: =D16*'K1 New'!$J$14 -> 0
A17: =A16+1 -> 10 | B17: Income taxes, any resulting fines, and zakat if charged to expenses | C17: Tax | E17: =D17*'K1 New'!$E$14 -> 0 | F17: =D17*'K1 New'!$J$14 -> 0
A18: =A17+1 -> 11 | B18: Employees’ share in statutory provident funds and social insurance | C18: Tax | E18: =D18*'K1 New'!$E$14 -> 0 | F18: =D18*'K1 New'!$J$14 -> 0
A19: =A18+1 -> 12 | B19: Value differences (materials/services) provided by related parties in excess of normal prices | C19: Mixed | E19: =D19*'K1 New'!$E$14 -> 0 | F19: =D19*'K1 New'!$J$14 -> 0
A20: =A19+1 -> 13 | B20: Expenses not related to the activity | C20: Mixed | E20: =D20*'K1 New'!$E$14 -> 0 | F20: =D20*'K1 New'!$J$14 -> 0
A21: =A20+1 -> 14 | B21: Maintenance and repair expenses in excess of the permissible limit | C21: Tax | E21: =D21*'K1 New'!$E$14 -> 0 | F21: =D21*'K1 New'!$J$14 -> 0
A22: =A21+1 -> 15 | B22: The user of the previous allocations returned to the pool | C22: Tax | E22: =D22*'K1 New'!$E$14 -> 0 | F22: =D22*'K1 New'!$J$14 -> 0
A23: =A22+1 -> 16 | B23: Provisions charged to period accounts | C23: Mixed | E23: =D23*'K1 New'!$E$14 -> 0 | F23: =D23*'K1 New'!$J$14 -> 0
A24: =A23+1 -> 17 | B24: Consumption differences (Table 3) | C24: Tax | E24: =D24*'K1 New'!$E$14 -> 0 | F24: =D24*'K1 New'!$J$14 -> 0
A25: =A24+1 -> 18 | B25: Loan returns in excess of the permissible limit | C25: Tax | E25: =D25*'K1 New'!$E$14 -> 0 | F25: =D25*'K1 New'!$J$14 -> 0
A26: =A25+1 -> 19 | B26: Irregular bad debts | C26: Mixed | E26: =D26*'K1 New'!$E$14 -> 0 | F26: =D26*'K1 New'!$J$14 -> 0
A27: =A26+1 -> 20 | B27: Any Other adjustments | C27: Mixed | E27: =D27*'K1 New'!$E$14 -> 0 | F27: =D27*'K1 New'!$J$14 -> 0
A28: =A27+1 -> 21 | B28: Actual zakat paid | C28: Mixed | E28: =D28*'K1 New'!$E$14 -> 0 | F28: =D28*'K1 New'!$J$14 -> 0
A29: 22 | B29: Share of Income from local subsidiaries & associates | C29: Mixed | E29: =D29*'K1 New'!$E$14 -> 0 | F29: =D29*'K1 New'!$J$14 -> 0
A30: 23 | B30: Dividend Income from local investments | C30: Mixed | E30: =D30*'K1 New'!$E$14 -> 0 | F30: =D30*'K1 New'!$J$14 -> 0
A31: 24 | B31: Reversal of provision for doubtful debts | C31: Mixed | E31: =D31*'K1 New'!$E$14 -> 0 | F31: =D31*'K1 New'!$J$14 -> 0
A34: Total | D34: =SUM(D8:D33) -> 0 | E34: =SUM(E8:E33) -> 0 | F34: =SUM(F8:F33) -> 0

Sheet ST 2 - Equity
A1: ='ST 1 - Adjustments to NP'!A1 -> Zakat/Tax payer's Name:
A2: ='ST 1 - Adjustments to NP'!A2 -> Unique No :
A3: ='ST 1 - Adjustments to NP'!A3 -> Year ended :
A6: Statement 2 : Equity & Other items
A7: Sr. No. | B7: Item | C7: ZR - reference | D7: Closing Balance
A8: 1 | B8: Share Capital - Closing balance راس المال | C8: 23(1) | D8: 0
A9: 2 | B9: Retained Earnings/(Loss) - Closing balance Less Dividend paid (even if paid from current year's profit) الأرباح المبقاه | C9: 23(1), 37(1) & 39 | D9: 0
A10: 3 | B10: Dividend declared but NOT paid (booked as liability - dividend payable) الأرباح تحت التوزيع | C10: 36
A11: 4 | B11: Reserves - Closing balances الاحتياطيات | C11: 23(1) | D11: 0
A12: 5 | B12: Provisions - Closing balance (Other than EOSB and other employees related provisions) المخصصات وفق رصيد اخر المدة | C12: 24 | E12: مخصص الزكاة
A13: 6 | B13: Shareholder Loan - Closing balance قروض الشركاء الدائنة | C13: 30 | D13: 0
A14: 7 | B14: Reduction in Equity due to Treasury Stocks اسهم خزانة | C14: 40
A15: 8 | B15: Reduction in Equity due to Employee Equity Stakes Program subject to conditions of Article 41 برنامج حصص اسهم الموظفين | C15: 41
A16: 9 | B16: Change in fair value التغيير في القيمة العادلة
A17: 10 | B17: Translation reserve احتياطي الترجمة
A18: 11 | B18: أخرى
A21: Total | D21: =SUM(D8:D20) -> 0

Sheet ST 3 - Liabilities
A1: ='ST 1 - Adjustments to NP'!A1 -> Zakat/Tax payer's Name:
A2: ='ST 1 - Adjustments to NP'!A2 -> Unique No :
A3: ='ST 1 - Adjustments to NP'!A3 -> Year ended :
A6: Statement 3: Liabilities & Other additions
A7: Sr. No. | B7: Classification | C7: Item | D7: ZR - reference | E7: Closing Balance
A8: 1 | B8: Non-current liabilites | C8: Debts classified Non-Current - Closing balance الديون غير المتداولة وفق رصيد اخر المدة | D8: 29(1)(a) | E8: 0
A9: =A8+1 -> 2 | B9: Non-current liabilites | C9: Provisions - Closing balance for EOSB and other employees related provisions المخصصات اخر المدة ـ مخصص مكافأة نهاية الخدمة ومخصص رصيد اجازات | D9: 24 & 29(1)(b) | E9: 0
A10: =A9+1 -> 3 | B10: Non-current liabilites | C10: Shareholder Loan - Closing balance قروض الشركاء الدائنة وفق رصيد اخر المدة | D10: 30 | E10: 0
A11: =A10+1 -> 4 | B11: Non-current liabilites | C11: Deferred Tax Liability - Closing balance الالنزام الضريبى المؤجل | D11: 29(1)(c)
A12: =A11+1 -> 5 | B12: Non-current liabilites | C12: Contract Liabilities - Closing balance التزامات العقد المثبته | D12: 29(1)(d) | E12: 0
A13: =A12+1 -> 6 | B13: Non-current liabilites | C13: Lease Liabilities - Closing balance التزامات عقود الايجار | D13: 29(1)(e) | E13: 0
A14: =A13+1 -> 7 | C14: Excluding corresponding Non-Current Liabilities when deduction of a Non-Current Asset is Not taken التزام غير متداول مقابل حسم اصل غير متداول | D14: 25 (2) | E14: 0
A15: =A14+1 -> 8 | C15: Addition of corresponding Current Liabilities when deduction of a Current Asset is taken اضافة التزام متداول مقابل حسم اصل متداول | D15: 25(3) & 29(2)(a) | E15: 0
A16: =A15+1 -> 9 | C16: If, Current Liabilities - Current Assets = Positive Difference, the difference will be added الفرق بين الالتزامات المتداولة وبين الأصول المتدولة بعد التسيب | D16: 29(2)(b) | E16: =F41 -> 0
A17: =A16+1 -> 10 | C17: Current liability, which was previously classified as Non-Current liability التزام متداول في حكم الالتزام غير المتداول | D17: 29(2)(c) | E17: 0
A19: Total | E19: =SUM(E8:E17) -> 0
A23: Total deductions | E23: ='K1 New'!N45 -> 0
A24: What is added to the base of debts | E24: =IF(E23>=E19,E19,E23) -> 0 | F24: 23(2)
C33: أجمالى الأصول المتداولة | D33: 0 | E33: 0 | F33: اجمالى الالتزامات المتداولة
C34: يحسم منه: | F34: يحسم منه :
C35: المخزون | D35: 0 | E35: 0 | F35: قروض قصيرة الاجل معاد تصنيفها
C36: موجودات عقود | D36: 0
C37: استثمارات بالقيمة العادلة | D37: 0
C38: 0 | D38: 0
C39: اجمالى ما يعاد تصنيفه | D39: =SUM(D35:D38) -> 0
C40: نسبة ما يعاد تنسيبه | D40: =D39/D33 -> #DIV/0! | E40: =D40 -> #DIV/0!
D41: =D33-D39 -> 0 | E41: =E33-E35 -> 0 | F41: =E41-D41 -> 0
C42: ما يضاف كألتزام | E42: =E40*E41 -> #DIV/0!
E44: =E42-D39 -> #DIV/0!

Sheet ST 4 - Fixed Assets & related
A1: ='ST 1 - Adjustments to NP'!A1 -> Zakat/Tax payer's Name:
A2: ='ST 1 - Adjustments to NP'!A2 -> Unique No :
A3: ='ST 1 - Adjustments to NP'!A3 -> Year ended :
A5: Statement 4: Fixed Assets
A6: Sr. no. | B6: Item | C6: ZR - reference | D6: Closing Balance
A7: 1 | B7: Fixed Assets - Closing balance الأصول الثابته | C7: 26(4) & 49 | D7: 0
A8: =A7+1 -> 2 | B8: Intangible Assets - Closing balance الأصول غير الملموسة | C8: 26(5) & 50 | D8: 0
A9: =A8+1 -> 3 | B9: Payments made for purchase of Fixed Assets - Closing balance دفعات شراء أصول ثابته | C9: 49(2) | D9: 0
A10: =A9+1 -> 4 | B10: Non-Current Investment Properties - Closing balance (not for reselling) العقارات الاستثمارية غير المتداولة وغير المعدة للبيع | C10: 49(8) | D10: 0
A11: =A10+1 -> 5 | B11: Right of Use Assets - Closing balance اصل حق الاستخدام المصنف غير المتداول | C11: 49(6) | D11: 0
A12: =A11+1 -> 6 | B12: Contract Costs classified as Non-Current Assets - Closing balance تكاليف العقد المصنفه غير المتداولة | C12: 49(7) | D12: 0
A13: =A12+1 -> 7 | B13: Raw Land used in activity - Closing balance الأراضي الخام المستخدمة في النشاط نا لم تكن معدة للبيع | C13: 49(9) | D13: 0
A14: =A13+1 -> 8 | B14: Employee Housing Ownership Program - Closing balnace (subject to conditions of Article 53 & 54) برنامج تملك مساكن الموظفين | C14: 49(10), 52 & 53 | D14: 0
A15: =A14+1 -> 9 | B15: Spare Parts - Closing balance المواد الخام و المواد غير المعدة للبيع كقطع الغيار | C15: 26(6) & 52(3) | D15: 0
A16: =A15+1 -> 10 | B16: Raw Material not held for Sale - Closing balance المواد الخام المصنفه اصل متداول - تنسيب_ | C16: 26(6), 52(4) & 25(3)
A20: Total | D20: =SUM(D7:D19) -> 0

Sheet ST 5 - Investments
A1: ='ST 1 - Adjustments to NP'!A1 -> Zakat/Tax payer's Name:
A2: ='ST 1 - Adjustments to NP'!A2 -> Unique No :
A3: ='ST 1 - Adjustments to NP'!A3 -> Year ended :
A5: Statement 5: Investments
A6: Sr. No. | B6: Investment details | C6: ZR - reference | D6: Closing Balance
A7: 1 | B7: Investments in in-Kingdom entities - Closing balance الاستثمارات في شركات داخل المملكة | C7: 26(1) & 43 | D7: 0
A8: 2 | B8: Investments in Foreign entities - Closing balance الاستثمارات في شركات خارج المملكة | C8: 26(2) & 44 | D8: 0
A9: 3 | B9: Investments in Investment Funds - Closing balance الاستثمارات في الصناديق الاستثمارية | C9: 26(3) & 45
A10: 4 | B10: Investment in Financing Fund - Closing balance الاستثمار في صناديق التمويل المباشر وغير المباشر | C10: 26(7)
A11: 5 | B11: Investment in Non-Governmental Sukuk and Bonds - Closing balance قيمة الاستثمار في الصكوك والسندات | C11: 26(8) & 55
A12: 6 | B12: Investments in entities which are not subjec to Zakat Regulations - Closing balance الاستثمار في شركات غير خاضعة لأحكام اللائحة | C12: 47
A16: Total | D16: =SUM(D7:D11) -> 0

Sheet ST 6 - Properties under develop
A1: ='ST 1 - Adjustments to NP'!A1 -> Zakat/Tax payer's Name:
A2: ='ST 1 - Adjustments to NP'!A2 -> Unique No :
A3: ='ST 1 - Adjustments to NP'!A3 -> Year ended :
A5: Statement 6: CWIP
A6: Project name | B6: ZR - reference | C6: Closing Balance
A7: CWIP - Closing balance (Not for reselling) الانشاءات الرأسمالية والمشروعات تحت الانشاء التي تنشأ لغرض استخدامها | B7: 49(5)
A18: Total | C18: =SUM(C7:C17) -> 0

Sheet ST 7 - Other deductions
A1: ='ST 1 - Adjustments to NP'!A1 -> Zakat/Tax payer's Name:
A2: ='ST 1 - Adjustments to NP'!A2 -> Unique No :
A3: ='ST 1 - Adjustments to NP'!A3 -> Year ended :
A5: Statement 7: Other Deductions
A6: Item | B6: ZR - reference | C6: Closing Balance
A7: Statutory Deposits - Closing balance الودائع النظامية | B7: 26(9) & 56
A8: Deferred Tax Assets - Closing balance الاص الضريبى المؤجل | B8: 26(10)
A9: Shareholder Loan given to Investee Entity - Closing balance قروض الشركاء المدينة | B9: 31
A10: Overdue Government Receivables - Closing balance (Classified as Current Assets) المستحقات الحكومية المتأخرة | B10: 32 & 25(3)
A11: Finance Lease Receivables الأصول المؤجرة تمويلياً | B11: 35, 49 & 74
A12: Biological Assets - Closing balance الاصول الحيوية بشرط تصنيفها أصول غير متداولة | B12: 51
A13: استثمارات بالقيمة العادلة | C13: 0
C14: 0
A16: Total | C16: =SUM(C7:C15) -> 0

Sheet ST 8 -Total assets
A1: ='ST 1 - Adjustments to NP'!A1 -> Zakat/Tax payer's Name:
A2: ='ST 1 - Adjustments to NP'!A2 -> Unique No :
A3: ='ST 1 - Adjustments to NP'!A3 -> Year ended :
A5: Statement 8 : Minumum Zakat Base
A6: Total assets according to the financial statements | B6: Closing Balance
A7: TOTAL NON-CURRENT ASSETS اجمالى الأصول غير المتداولة | B7: 0
A8: TOTAL CURRENT ASSETS أجمالى الأصول المتداولة | B8: 0
A16: Total | B16: =SUM(B7:B15) -> 0

Sheet ST 9-Application of Article 25
A1: ='ST 1 - Adjustments to NP'!A1 -> Zakat/Tax payer's Name:
A2: ='ST 1 - Adjustments to NP'!A2 -> Unique No :
A3: ='ST 1 - Adjustments to NP'!A3 -> Year ended :
A5: Statement 9 : Application of Article
A6: Items classified as current assets and included in the deductions to meet the conditions of deduction
A7: Item | C7: Amount
A8: Spare parts (Current asset deducted from zakat base) | C8: 0
C9: 0
A10: Total | C10: =SUM(C8:C9) -> 0
A11: Current liability added to the zakat base - (deducted current asset/ total current assets) x current liabilities) | C11: =C10/C23*C27 -> #DIV/0!
A14: Items classified as non-current assets and not included in the deductions of the Zakat base.
A15: Item | C15: Amount
A16: Undeductable Assets الأصول غير المحسومة | C16: 0
A18: Total | C18: =SUM(C16:C17) -> 0
A19: Non-current liability excluded from the zakat base - (Non-current asset excluded / total non-current assets) x Non-Current Liabilities) | C19: =C18/C24*C28 -> #DIV/0!
A23: Total Current assets as per FS اجمالى الأصول المتداولة | C23: 0
A24: Total Non-current assets as per FS اجمالى الأصول غير المتداولة | C24: 0
A25: Total Assets as per FS الاجمالى الأصول وفق القوائم المالية | C25: =SUM(C23:C24) -> 0
A27: Total Current Liabilities as per FS اجمالى الخصول المتداولة | C27: 0
A28: Total Non-current Liabilities ST3 اجمالى الخصوم غير المتداولة | C28: 0
A29: Total Liabilities as per FS اجمالى الخصوم وفق القوائم المالية | C29: =SUM(C27:C28) -> 0

Sheet TB 2022

Sheet Page 1
A2: Shuaibah Water & Electricity Company | M2: 3000013966 | N2: 2016
A3: Unified Return for Taxpayer Maintaining Statutory Accounting Books and Records (Zakat/Tax/Mixed)
A4: A- Revenue | N4: Total
A5: Revenue from main activity ( 10100 ) | B5: 10101 | C5: Contracting activity (schedule 1)
B6: 10102 | C6: Finance lease activity
B7: 10103 | C7: Insurance activity (schedule 2) | M7: =IFERROR(#REF!,0) -> 0
B8: 10104 | C8: Real estate activity
B9: 10105 | C9: Banking activity
B10: 10106 | C10: Natural gas activity
B11: 10107 | C11: Service/industrial/trading activity | M11: 1090871521
A12: 10100 | B12: Revenue from main income | N12: =SUM(M5:M11) -> 1090871521
A13: Other Income ( 10200) | B13: 10201 | C13: Capital gains (losses) from assets disposal
B14: 10202 | C14: Commissions
B15: 10203 | C15: Loan fees (interest and bank charges) | M15: 3369527
B16: 10204 | C16: Unrealized gains (losses) from investment securities (schedule 24) | M16: =#REF! -> #REF!
B17: 10205 | C17: Company's share in the investee's profits (schedule 25) | M17: =#REF! -> #REF!
B18: 10206 | C18: Gain on sale of investment in financial securities (schedule 17-a) | M18: =#REF! -> #REF!
B19: 10207 | C19: Gain on sale of investment in companies (schedule 17-b) | M19: =#REF! -> #REF!
B20: 10208 | C20: Refunded expenses/previously written off bad debts collected
B21: 10209 | C21: Received compensations
B22: 10210 | C22: Patent / Franchise rights
B23: 10211 | C23: Rent
B24: 10212 | C24: Miscellaneous (other income) | M24: =#REF! -> #REF!
A25: 10200 | B25: Total other income (Total of items 10201 to 10212) | N25: =SUM(M13:M24) -> #REF!
A26: 10300 | B26: Total revenue (10100 + 10200) less: | N26: =N25+N12 -> #REF!
A27: B- Costs and expenses
A29: Cost of goods sold (10400) | B29: 10401 | C29: Inventory at beginning of period (raw materials + under production + finished goods)
B30: 10402 | C30: Purchases from abroad (imports)
B31: 10403 | C31: Local purchases
B32: 10404 | C32: Less: Inventory at end of period (raw materials + under production + finished goods)
A33: 10400 | B33: Costs of goods sold | N33: =SUM(M29:M31)-M32 -> 0
A34: Direct expenses (10500) | B34: 10501 | C34: Custom duties
B35: 10502 | C35: Shipment and clearance charges
B36: 10503 | C36: Direct wages
B37: 10504 | C37: Subcontractors (schedule 4) | L37: Applicable | M37: =#REF! -> #REF!
B38: 10505 | C38: Fixed assets depreciation as per books (included in direct expenses) | M38: 279943755
B39: 10506 | C39: Rent (5-a-1)
B40: 10507 | C40: Repair and maintenance expenses | M40: 18495623
B41: 10508 | C41: Hire of equipment (schedule 5-b) | M41: =#REF! -> #REF!
B42: 10510 | C42: Loan fees (interest and bank charges)
...

Sheet Page 2
A3: C- Net adjustments to book profit/ (loss)
A5: 10900 | B5: BOOK NET PROFIT / LOSS, Add: | M5: =IFERROR((('Page 1'!N70:N70)),0) -> 0
A6: EXPENSES NOT ALLOWABLE UNDER REGULATIONS (11000 ) | B6: 11001 | C6: Partners' salaries, administrative fees and other payments - in case of non-compliance
B7: 11002 | C7: Depreciation difference (schedule 10) | K7: Applicable | L7: =-(('10-A'!L12+'10-B'!K14)-('Page 1'!M38+'Page 1'!M51)) -> 279943755
B8: 11003 | C8: (Royalties, financial charges, loan fees, indirect expenses) for Head Office
B9: 11004 | C9: Social insurance paid abroad
B10: 11005 | C10: Employees' share of statutory provident funds and social insurance
B11: 11006 | C11: Employer's contributions for retirement funds in excess of statutory limit
B12: 11007 | C12: Repairs and maintenance expenses in excess of statutory limit (schedule 10 - b) | L12: ='10-B'!N14 -> 0
B13: 11008 | C13: Provisions charged to the period (schedule 20) | K13: Applicable | L13: =#REF! -> #REF!
B14: 11009 | C14: Reserves charged to the period
B15: 11010 | C15: Value differences (materials & services) provided by related parties in excess of market prices
B16: 11011 | C16: Expenses not related to the activity and entertainment expenses
B17: 11012 | C17: Corporate tax and zakat charged to expenses
B18: 11013 | C18: Non-statutory fines and penalties
B19: 11014 | C19: Non-statutory school fees for employees children
B20: 11015 | C20: Non-statutory bad debts written off
B21: 11016 | C21: Others (schedule 9) | K21: Applicable | L21: =#REF! -> #REF!
A22: 11000 | B22: Total expenses non-deductible (11001 TO 11016 ) | M22: =SUM(L6:L21) -> #REF!
A23: 11100 | B23: Net adjusted profit / (loss) prior to exemptions (10900 + 11000) | M23: =M5+M22 -> #REF!
A24: 11201 | B24: Add: Capital losses (Gains to be deducted) on sale of fixed assets, if straight line method is adopted
A25: 11200 | B25: Net adjusted subject profit (11100 + 11201 + 11202 + 11203 ) | M25: =M23+M24 -> #REF!

Sheet Page 3
A3: D- Computation of tax on Non-Saudi shareholder's
A4: 11300 | B4: Saudi shareholder's share of adjusted profit / (loss) (11200 x Saudi shareholder's share of profit): | L4: 0.6863 | M4: =IF(L4=0,0,'Page 2'!M25:M25*'Page 3'!L4) -> #REF!
A5: 11400 | B5: Non-Saudi share holder's share of adjusted profit/ (Loss) (11200 X non Saudi shareholder's of profit, add/ Less: | L5: 0.3137 | M5: =IF(L5=0,0,'Page 2'!M25:M25*L5) -> #REF!
A6: Non-Saudi shareholder's additions ( 11500 ) | B6: 11501 | C6: His share in loan fees in excess of allowable limit (schedule 16) | L6: =#REF! -> #REF!
B7: 11502 | C7: His share in realized capital losses from disposal of securities in the capital market
B8: 11503 | C8: His share in the company's share of investee's losses
B9: 11504 | C9: Non-Saudi shareholder's salaries and wages
A10: 11500 | B10: Non-Saudi total additions (11501 + 11502 + 11503) | M10: =SUM(L6:L9) -> #REF! | O10: =M5+M10-L11 -> #REF!
A11: Non-Saudi shareholder's deductions ( 11600 ) | B11: 11601 | C11: Non -Saudi share of utilized provisions previously added back to base | L11: =(#REF!*'Page 3'!L5) -> #REF!
B12: 11602 | C12: His share in realized capital gains from disposal of securities in the capital market
B13: 11603 | C13: His share in the losses brought forward restricted to 25% of (its share of profit per declaration) | L13: ='16-Accumulated losses Non Saudi'!D13 -> 0
B14: 11604 | C14: His share in the company's share of investee's profits (subject to double taxation provisions)
A15: 11600 | B15: Total deductions from the non-Saudi share ( 11601 + 11602 + 11603 + 11604 ) | M15: =SUM(L11:L14) -> #REF!
A16: 11700 | B16: Tax base subject to tax (11400 + 11500 - 11600 ) | M16: =M5+M10-M15 -> #REF!
A17: 11710 | B17: Tax base subject to tax for non-resident insurance companies operating through permanent establishment per schedule (schedule 22) | L17: Applicable
A19: Taxes due ( 11700 ) | B19: 11701 | C19: Income tax due on the share of Non-Saudi shareholder (11700 x 20%) | L19: =M16*20% -> #REF!
B20: 11702 | C20: Income tax on Oil and Hydrocarbons production (11700 x 85%)
B21: 11703 | C21: Income tax on Natural Gas Investment (11700 x 30%)
B22: 11704 | C22: Income tax on Natural Gas Investment (attached exhibit)
A23: 11700 | B23: Total taxes due (Total of items 11701 to 11704 ) | M23: =SUM(L19:L22) -> #REF!
A25: E - COMPUTATION OF ZAKAT DUE ON THE SAUDI SIDE
A26: 11800 | B26: Saudi Shareholder's share of capital (schedule 11) | M26: =#REF! -> #REF!
A27: Saudi shareholder's additions ( 11900) | B27: Add his share in:
B28: 11901 | C28: Adjusted profits / (loss)(11300 ) | L28: =M4 -> #REF!
B29: 11902 | C29: Retained earnings (schedule 18) | K29: Applicable | L29: =#REF!+#REF! -> #REF!
B30: 11903 | C30: Provisions (schedule 20 ) | L30: =(#REF!-#REF!)*'Page 3'!L4 -> #REF!
B31: 11904 | C31: Reserves (schedule 21) | K31: Applicable | L31: =IF(L4=0,0,(#REF!-#REF!+#REF!)*L4) -> #REF!
B32: 11905 | C32: Loans and similar items (schedule 15 ) | K32: Applicable | L32: =#REF! -> #REF!
B33: 11906 | C33: Shareholders credit current account balance (schedule 14 ) | K33: Applicable | L33: =#REF! -> #REF!
B34: 11907 | C34: Other additions (schedule 12 ) | K34: Applicable | L34: =IF(L4=0,0,#REF!*L4) -> #REF!
A35: 11900 | B35: Total additions (Total items from 11901 to 11906 ) | M35: =SUM(L28:L34) -> #REF!
A36: Saudi shareholder's deductions ( 12000) | B36: less his share in :
B37: 12001 | C37: Net fixed assets and similar items (Schedule 10-a or 10-b) | L37: =(('10-B'!O14)+('10-B'!D14*50%)-('10-B'!G14*50%))*68.63% -> 0
B38: 12002 | C38: Investments (from Schedule 17-a or 17-b) | K38: Applicable | L38: =IF(L4=0,0,(#REF!+#REF!)*L4) -> #REF!
B39: 12003 | C39: Adjusted brought forward losses (Schedule 19-b) | K39: Applicable
B40: 12004 | C40: Incorporation expenses and similar items
B41: 12005 | C41: Other deductions (Schedule 13) | K41: Applicable | L41: =IF(L4=0,0,#REF!*L4) -> #REF!
A42: 12000 | B42: Total deductions (Total items from 12001 to 12005) | M42: =SUM(L36:L41) -> #REF!
A43: 12100 | B43: Zakat base 11800 + 11900 - 12000 ) | M43: =M26+M35-M42+1 -> #REF!
A45: 12500 | B45: Zakat due (12100 or 12400, which is higher X 2.5%) | M45: =IF(MAX(L28,M43)>0,MAX(L28,M43)*2.5%,0) -> #REF!
...

Sheet Page 4
A4: G- BALANCE SHEET AS AT 31 / 12 /2016
A5: Items | M5: Beginning of period | N5: End of period
A6: Current assets ( 13300 ) | B6: 13301 | C6: Cash on hand and at banks | M6: 288183000
B7: 13302 | C7: Short term investments
B8: 13303 | C8: Debtors and debit balances | M8: =169540000+751000+1575000+1229000+383000 -> 173478000
B9: 13304 | C9: Stock
B10: 13305 | C10: Accrued income
B11: 13306 | C11: Prepaid expenses | M11: 6959000
B12: 13307 | C12: Amounts due from related parties (Schedule 26) | L12: Applicable | M12: =#REF! -> #REF! | N12: =#REF! -> #REF!
B13: 13308 | C13: Other current assets
A14: 13300 | B14: Total current assets | M14: =SUM(M6:M13) -> #REF! | N14: =SUM(N6:N13) -> #REF!
A15: Non-current assets ( 13400 ) | B15: 13401 | C15: Long term investments
B16: 13402 | C16: Net property (fixed assets NBV) | M16: =7036055000-M17 -> 7027784000 | N16: =7036055000-N17 -> 7036055000
B17: 13403 | C17: Construction in progress / (work in progress) | M17: 8271000
B18: 13404 | C18: Incorporation expenses
B19: 13405 | C19: Other non-current assets
A20: 13400 | B20: Total non-current assets | M20: =SUM(M15:M19) -> 7036055000 | N20: =SUM(N15:N19) -> 7036055000
A21: Intangible assets (13500) | B21: 13501 | C21: Patent
B22: 13502 | C22: Goodwill
A23: 13500 | B23: Total intangible assets | M23: =SUM(M21:M22) -> 0 | N23: =SUM(N21:N22) -> 0
B24: Total assets ( 13300 + 13400 + 13500 ) | M24: =SUM(M14,M20,M23) -> #REF! | N24: =SUM(N14,N20,N23) -> #REF!
A25: Current liabilities (13600 ) | B25: 13601 | C25: Short term notes payable
B26: 13602 | C26: Creditors | M26: =4272000+2241000+100553000+438047000-538600000 -> 6513000 | N26: =4272000+2241000+100553000+438047000-538600000 -> 6513000
B27: 13603 | C27: Accrued expenses | M27: 190848105 | N27: =145249000+20481000+5170000+12819000+8166000-#REF!-961 -> #REF!
B28: 13604 | C28: Dividends payable
B29: 13605 | C29: Current portion of long term loans | M29: 404261000 | N29: 404261000
B30: 13606 | C30: Short term loans (Schedule 15)
B31: 13607 | C31: Amounts due to related parties | M31: 90000 | N31: 90000
A32: 13600 | B32: Total current liabilities | M32: =SUM(M25:M31) -> 601712105 | N32: =SUM(N25:N31) -> #REF!
A33: Non-current liabilities (13700) | B33: 13701 | C33: Long term loans ( Schedule 15) | M33: 4542244000 | N33: 4542244000
B34: 13702 | C34: Long term notes payable
B35: 13703 | C35: Other provisions | M35: 209770895 | N35: =#REF! -> #REF!
B36: 13704 | C36: Shareholders' current account (Schedule 14 )
B37: 13705 | C37: Amounts due to related parties (schedule 27) | L37: Applicable | M37: =#REF! -> #REF! | N37: =#REF! -> #REF!
A38: 13700 | B38: Total non-current liabilities | M38: =SUM(M33:M37) -> #REF! | N38: =SUM(N33:N37) -> #REF!
A39: Shareholders' equity ( 13800) | B39: 13801 | C39: Capital ( Schedule 11 ) | M39: 1560500000 | N39: =#REF! -> #REF!
B40: 13802 | C40: Profit/(loss) for the period | M40: 230382000 | N40: ='Page 1'!N70 -> #REF!
B41: 13803 | C41: Reserves (Schedules 21 ) | M41: 47214000 | N41: =#REF! -> #REF!
B42: 13804 | C42: Retained earnings (Schedule 18 ) | M42: 295042000 | N42: =#REF! -> #REF!
B43: 13805 | C43: Others | M43: 18750000 | N43: 18750000
...

Sheet 5 a 2
A1: Schedule 5-A-2: Rents reported in indirect expenses
A2: DZIT assigned No. or CR No. | B2: Name of lessor | C2: Address | D2: Balance at the beginning of the year credit/ (debit) | E2: Rents accrued and charged during the year reported in indirect expenses | F2: Paid during the year | G2: Balance at the end of the year credit/ (debit) 7 = 4 + 5 - 6
A6: 1 | B6: 2 | C6: 3 | D6: 4 | E6: 5 | F6: 6
A7: Government Entity | B7: Saline Water Conversion Corp. (SWCC) | C7: West Coast, Prince M. Bin Abdulaziz St., Jeddah, Saudi Arabia | E7: 1000 | F7: 1000 | G7: =D7+E7-F7 -> 0
G8: =D8+E8-F8 -> 0
A9: Total | D9: =SUM(D7:D8) -> 0 | E9: =SUM(E7:E8) -> 1000 | F9: =SUM(F7:F8) -> 1000 | G9: =SUM(G7:G8) -> 0

Sheet 10 - Loans (2)
A1: =IF(#REF!=0,"Zakat/Tax payer's Name:…………………..","Zakat/Tax payer's Name: "&#REF!) -> #REF!
A2: =IF(#REF!=0,"Unique No :","Unique No : "&RIGHT(#REF!,LEN(#REF!)-FIND(".",#REF!))) -> #REF!
A3: =IF(#REF!=0,"Year ended : ","Year ended :" &RIGHT(#REF!,LEN(#REF!)-5)) -> #REF!
A5: Statement 10: Movement of loans - Return item no. 11106
A6: Details of Lending party | B6: Local/Foreign | C6: Balance at the beginning of the period | D6: Amount settled during the year | E6: Addition to loans during the year | F6: Balance at the end of the period | G6: Amount of loans utilized in deducted items | H6: Date of loans start | I6: Date of loans cleared | J6: Amount to be added to the base
A7: 1 | B7: 2 | C7: 3 | D7: 4 | E7: 5 | F7: 6= 3 + 5 - 4
A8: Riyadh Bank | B8: local | C8: 367666845 | F8: =C8+E8-D8 -> 367666845 | J8: =F8 -> 367666845
A9: Bank Al Jazira | B9: local | C9: 247160655 | F9: =C9+E9-D9 -> 247160655 | J9: =F9 -> 247160655
A10: Al Rajhi Bank | B10: local | C10: 3.5595063e+08 | E10: 4.4578054e+08 | F10: =C10+E10-D10 -> 8.0173117e+08 | G10: =E10 -> 4.4578054e+08 | H10: 17-1-2022 | J10: =F10 -> 8.0173117e+08
A11: Abu Dhabi Islamic Bank | B11: Foreign | C11: 1.5393381e+08 | E11: 1.9278151e+08 | F11: =C11+E11-D11 -> 3.4671532e+08 | G11: =E11 -> 1.9278151e+08 | H11: 17-1-2022 | J11: =F11 -> 3.4671532e+08
A12: Mizuho Bank | B12: Foreign | C12: 1.2962848e+08 | E12: 1.6234232e+08 | F12: =C12+E12-D12 -> 2.919708e+08 | G12: =E12 -> 1.6234232e+08 | H12: 17-1-2022 | J12: =F12 -> 2.919708e+08
A13: Riyadh Bank | B13: local | C13: 1.4046483e+08 | E13: 1.759134e+08 | F13: =C13+E13-D13 -> 3.1637822e+08 | G13: =E13 -> 1.759134e+08 | H13: 17-1-2022 | J13: =F13 -> 3.1637822e+08
A14: Capitalised provision | F14: =C14+E14-D14 -> 0 | G14: =E14 -> 0 | J14: =F14-E14+G14 -> 0
A15: Total | C15: =SUM(C8:C13) -> 1.3948052e+09 | D15: =SUM(D8:D13) -> 0 | E15: =SUM(E8:E14) -> 9.7681777e+08 | F15: =SUM(F8:F14) -> 2.371623e+09 | G15: =SUM(G8:G14) -> 9.7681777e+08 | J15: =SUM(J8:J14) -> 2.371623e+09
A17: Opening balance | B17: =C15 -> 1.3948052e+09 | I17: Total Deductions | J17: =#REF! -> #REF!
A18: Less: Paid during the year | B18: =-D15 -> 0 | I18: Added to ZAKAT base | J18: =J15 -> 2.371623e+09
B19: =SUM(B17:B18) -> 1.3948052e+09
A20: Saudi shareholding | B20: =#REF! -> #REF! | I20: Restricting loan as per article 4 (3)c | J20: =MIN(J17,J18) -> #REF!
A21: Amount subject to zakat (Line no. 11906) | B21: =B19*B20 -> #REF!
D24: Op CWIP | E24: 1384853727 | F24: Op Cash | G24: 54006437 | I24: -976255450
D25: Cl CWIP | E25: 2329233662 | F25: Closing cash | G25: 116007862 | I25: -938871947
E26: =E25-E24 -> 944379935 | F26: Diff | G26: =G25-G24 -> 62001425 | I26: =I24-I25 -> -37383503

Sheet 10-B
A1: =IF(#REF!=0,"Zakat/Tax payer's Name:…………………..","Zakat/Tax payer's Name: "&#REF!) -> #REF!
A2: =IF(#REF!=0,"Unique No :","Unique No : "&RIGHT(#REF!,LEN(#REF!)-FIND(".",#REF!))) -> #REF!
A3: =IF(#REF!=0,"Year ended : ","Year ended :" &RIGHT(#REF!,LEN(#REF!)-5)) -> #REF!
A5: Statement 10-B: Fixed assets depreciation as per Article (17) of Income tax law
A6: Category number | B6: Group value at the end of prior year | C6: Cost of additions during prior year | D6: Cost of additions during current year | E6: 50% of the total cost of additions during the current and prior years | F6: Total sale proceeds for assets disposed off during prior year | G6: Total sale proceeds for assets disposed off during current year | H6: 50% of the total sale proceeds for assets disposed off during the current and prior year | I6: Group balance at the end of the year | J6: Depreciation rate | K6: Depreciation charge | L6: Group balance at the end of current year | M6: Repair and maintenance expenses related to the group | N6: Repair and maintenance expenses over 4% | O6: Group balance at the end of the current year
B7: 1 | C7: 2 | D7: 3 | E7: 4 = (2 + 3)* 50 % | F7: 5 | G7: 6 | H7: 7= (5 + 6)*50 % | I7: 8 = 1 + 4 -7 | J7: 9 | K7: 10 = 8 * 9 | L7: 11 | M7: 12 | N7: 13 | O7: 14 = 11 + 13
A8: Land | E8: =(C8+D8)*0.5 -> 0 | H8: =(F8+G8)*0.5 -> 0 | I8: =B8+E8-H8 -> 0 | J8: 0 | K8: =I8*J8 -> 0 | N8: =IF((M8-L8*0.04)>0,(M8-L8*0.04),0) -> 0 | O8: =L8+N8 -> 0
A9: Fixed buildings | D9: =D21 -> 0 | E9: =(C9+D9)*0.5 -> 0 | H9: =(F9+G9)*0.5 -> 0 | I9: =B9+E9-H9 -> 0 | J9: 0.05 | K9: =I9*J9 -> 0 | L9: =I9-K9 -> 0 | N9: =IF((M9-L9*0.04)>0,(M9-L9*0.04),0) -> 0 | O9: =L9+N9 -> 0
A10: Moveable industrial and agricultural buildings | C10: 0 | E10: =(C10+D10)*0.5 -> 0 | H10: =(F10+G10)*0.5 -> 0 | I10: =B10+E10-H10 -> 0 | J10: 0.1 | K10: =I10*J10 -> 0 | L10: =I10-K10 -> 0 | N10: =IF((M10-L10*0.04)>0,(M10-L10*0.04),0) -> 0 | O10: =L10+N10 -> 0
A11: Factories, equipment, machinery, hardware and software (computer programs) and equipment including passenger and freight vehicles. | C11: =C23+C24+C25 -> 0 | D11: =D29 -> 0 | E11: =(C11+D11)*0.5 -> 0 | H11: =(F11+G11)*0.5 -> 0 | I11: =B11+E11-H11 -> 0 | J11: 0.25 | K11: =I11*J11 -> 0 | L11: =I11-K11 -> 0 | N11: =IF((M11-L11*0.04)>0,(M11-L11*0.04),0) -> 0 | O11: =L11+N11 -> 0
A12: Cost of geological surveying, exploration, discovery and initial works to extract natural resources and develop fields. | E12: =(C12+D12)*0.5 -> 0 | H12: =(F12+G12)*0.5 -> 0 | I12: =B12+E12-H12 -> 0 | J12: 0.2 | K12: =I12*J12 -> 0 | N12: =IF((M12-L12*0.04)>0,(M12-L12*0.04),0) -> 0 | O12: =L12+N12 -> 0
A13: All other assets, tangible and intangible, not included in the foregoing categories such as furniture, aircrafts, ships, trains and goodwill. | C13: =C31 -> 0 | D13: =D32 -> 0 | E13: =(C13+D13)*0.5 -> 0 | H13: =(F13+G13)*0.5 -> 0 | I13: =B13+E13-H13 -> 0 | J13: 0.1 | K13: =I13*J13 -> 0 | L13: =I13-K13 -> 0 | N13: =IF((M13-L13*0.04)>0,(M13-L13*0.04),0) -> 0 | O13: =L13+N13 -> 0
A14: Total | B14: =SUM(B8:B13) -> 0 | C14: =SUM(C8:C13) -> 0 | D14: =SUM(D8:D13) -> 0 | E14: =SUM(E8:E13) -> 0 | F14: =SUM(F8:F13) -> 0 | G14: =SUM(G8:G13) -> 0 | H14: =SUM(H8:H13) -> 0 | I14: =SUM(I8:I13) -> 0 | K14: =SUM(K8:K13) -> 0 | L14: =SUM(L8:L13) -> 0 | M14: =SUM(M8:M13) -> 0 | N14: =SUM(N8:N13) -> 0 | O14: =SUM(O8:O13) -> 0
J16: As per FS | K16: =#REF! -> #REF!
J17: Diff | K17: =K16-K14 -> #REF!
A19: Group description | B19: Assets | C19: Additions during 2020 | D19: Additions during 2021 | E19: Total | F19: Sale proceeds in 2020 | G19: Sale proceeds in 2021 | H19: Total | I19: Repair and maintenance
A20: First | B20: Building | E20: =SUM(C20:D20) -> 0 | F20: 0 | G20: 0 | H20: =SUM(F20:G20) -> 0 | I20: 0
A21: Sub Total | C21: =SUM(C20) -> 0 | D21: =SUM(D20) -> 0 | E21: =SUM(E20) -> 0 | F21: =SUM(F20) -> 0 | G21: =SUM(G20) -> 0 | H21: =SUM(H20) -> 0 | I21: =SUM(I20) -> 0
A23: Third | B23: Plant ant machinery | E23: =SUM(C23:D23) -> 0 | F23: 0 | G23: 0 | H23: =SUM(F23:G23) -> 0 | I23: 0
A24: Third | B24: Motor vehicles | E24: =SUM(C24:D24) -> 0 | F24: 0 | G24: 0 | H24: =SUM(F24:G24) -> 0 | I24: 0
A25: Third | B25: Office Equipment | E25: =SUM(C25:D25) -> 0 | F25: 0 | G25: 0 | H25: =SUM(F25:G25) -> 0 | I25: 0
A26: Third | B26: Computer hardware | E26: =SUM(C26:D26) -> 0 | F26: 0 | G26: 0 | H26: =SUM(F26:G26) -> 0 | I26: 0
A27: Third | B27: Spares | E27: =SUM(C27:D27) -> 0 | F27: 0 | G27: 0 | H27: =SUM(F27:G27) -> 0 | I27: 0
A28: Third | B28: Software | E28: =SUM(C28:D28) -> 0 | F28: 0 | G28: 0 | H28: =SUM(F28:G28) -> 0 | I28: 0
A29: Sub Total | C29: =SUM(C23:C28) -> 0 | D29: =SUM(D23:D28) -> 0 | E29: =SUM(E23:E27) -> 0 | H29: =SUM(H23:H28) -> 0 | I29: =SUM(I23:I28) -> 0
A31: Fifth | B31: Furniture and fixture | E31: =SUM(C31:D31) -> 0 | F31: 0 | G31: 0 | H31: =SUM(F31:G31) -> 0 | I31: 0
A32: Sub Total | C32: =SUM(C31) -> 0 | D32: =SUM(D31) -> 0 | E32: =SUM(E31) -> 0 | I32: =SUM(I31) -> 0
A33: Grand total | C33: =C21+C29+C32 -> 0 | D33: =D21+D29+D32 -> 0 | E33: =E21+E29+E32 -> 0 | F33: =F32+F29+F21 -> 0 | G33: =G32+G29+G21 -> 0 | H33: =H21+H29+H31 -> 0 | I33: =I32+I29+I21 -> 0

Sheet Fixed assets
A1: =IF(#REF!=0,"Zakat/Tax payer's Name:…………………..","Zakat/Tax payer's Name: "&#REF!) -> #REF!
A2: =IF(#REF!=0,"Unique No :","Unique No : "&RIGHT(#REF!,LEN(#REF!)-FIND(".",#REF!))) -> #REF!
A3: =IF(#REF!=0,"Year ended : ","Year ended :" &RIGHT(#REF!,LEN(#REF!)-5)) -> #REF!
A5: Schedule : Net fixed assets and equivalent - Return item no. 11301
A6: Description | B6: Saudi Riyals
A8: Fixed Asset Deduction As per Zakat regulations
A9: Net book value of fixed assets at year end (excluding CWIP) | B9: 0

Sheet 10-A
A1: SCHEDULE 10- A: Fixed assets depreciation using straight line method
A2: Category number | B2: Historical cost balance at the beginning of the year as per accounts | C2: Cost of additions during current year | D2: Cost of disposals during the current year | E2: Historical cost balance at the end of the year as per accounts | F2: Book accumulated depreciation at the beginning of the year as per accounts | G2: Depreciation rate as per accounts | H2: Book depreciation as per accounts | I2: Book accumulated depreciation at the end of the year as per accounts | J2: Net historical cost balance at the end of the year as per accounts | K2: Depreciation rate as per the DZIT's circular | L2: Depreciation charge as per the DZIT's circular | M2: Amount deductible from zakat base
B5: 1 | C5: 2 | D5: 3 | E5: 4 = 1 + 2 - 3 | F5: 5 | G5: 6 | H5: 7 | I5: 8 = 5 + 7 | J5: 9 = 4 - 8 | K5: 10 | L5: 11 = 4 × 10 | M5: 12 = 4 - 5 - 11
A6: Land | E6: =B6+C6-D6 -> 0 | I6: =F6+H6 -> 0 | J6: =E6-I6 -> 0 | K6: 0 | L6: =K6*E6 -> 0 | M6: =E6-F6-L6 -> 0
A7: First | E7: =B7+C7-D7 -> 0 | I7: =F7+H7 -> 0 | J7: =E7-I7 -> 0 | K7: 0.05 | L7: =K7*E7 -> 0 | M7: =E7-F7-L7 -> 0
A8: Second | E8: =B8+C8-D8 -> 0 | H8: N/A | J8: =E8-I8 -> 0 | K8: 0.1 | L8: =K8*E8 -> 0 | M8: =E8-F8-L8 -> 0
A9: Third | E9: =B9+C9-D9 -> 0 | I9: =F9+H9 -> 0 | J9: =E9-I9 -> 0 | K9: 0.25 | L9: =K9*E9 -> 0 | M9: =E9-F9-L9 -> 0
A10: Fourth | E10: =B10+C10-D10 -> 0 | I10: =F10+H10 -> 0 | J10: =E10-I10 -> 0 | K10: 0.2 | L10: =K10*E10 -> 0 | M10: =E10-F10-L10 -> 0
A11: Fifth | E11: =B11+C11-D11 -> 0 | I11: =F11+H11 -> 0 | J11: =E11-I11 -> 0 | K11: 0.1 | L11: =K11*E11 -> 0 | M11: =E11-F11-L11 -> 0
A12: Total | B12: =SUM(B6:B11) -> 0 | C12: =SUM(C6:C11) -> 0 | D12: =SUM(D6:D11) -> 0 | E12: =SUM(E6:E11) -> 0 | F12: =SUM(F6:F11) -> 0 | G12: =SUM(G6:G11) -> 0 | H12: =SUM(H6:H11) -> 0 | I12: =SUM(I6:I11) -> 0 | J12: =SUM(J6:J11) -> 0 | L12: =SUM(L6:L11) -> 0 | M12: =SUM(M6:M11) -> 0

Sheet 16-Accumulated losses Non Saudi
A1: =IF(#REF!=0,"Zakat/Tax payer's Name:…………………..","Zakat/Tax payer's Name: "&#REF!) -> #REF! | F1: Profit
A2: =IF(#REF!=0,"Unique No :","Unique No : "&RIGHT(#REF!,LEN(#REF!)-FIND(".",#REF!))) -> #REF! | F2: Loss
A3: =IF(#REF!=0,"Year ended : ","Year ended :" &RIGHT(#REF!,LEN(#REF!)-5)) -> #REF!
A5: Statement 16: Losses carried forward - Non- Saudi partner - Return item no. 12003
A6: Year | B6: Profit/Loss | C6: Current year profit/ (Loss) | D6: Losses Adjustments | E6: Losses amount carried forward
C17: =C20 -> #REF! | D17: =C17*25% -> #REF! | E17: =E16+D17 -> #REF!
A19: Details
A20: Net adjusted profit for Non-Saudi Shareholder | C20: =#REF! -> #REF!

Sheet 14
A1: Schedule 14: Movement of partners current account
A2: Amount to be added to zakat base | B2: In respect of partner financing during current year, state the following | D2: Balance at the end of the period | E2: Deductions during current year | H2: Additions during current year | K2: Balance at the beginning of the period | L2: Shareholder name
B4: Amount of financing utilized in trading activity 10 | C4: اAmount of financing utilized in assets additions 9 | E4: Partners withdrawals 7 | F4: Brought forward to set-off carried forward losses 6 | G4: Carried forward to any item of the financial statement 5 | H4: Carried forward from any item of the financial statement 4 | I4: المحول من الأرباح المرحلة 3 | J4: Financing by the shareholder 2 | K4: 1
D5: = 1 + 2 + 3 + 4 '- 5 - 6 - 7
L6: Saudi/GCC resident
L7: Non-Saudi
L11: Total

Sheet 17 - Insurance Companies
A1: =IF(#REF!=0,"Zakat/Tax payer's Name:…………………..","Zakat/Tax payer's Name: "&#REF!) -> #REF!
A2: =IF(#REF!=0,"Unique No :","Unique No : "&RIGHT(#REF!,LEN(#REF!)-FIND(".",#REF!))) -> #REF!
A3: =IF(#REF!=0,"Year ended : ","Year ended :" &RIGHT(#REF!,LEN(#REF!)-5)) -> #REF!
A5: Statement 17: Insurance companies - permanent establishment - Return item no. 11710
B6: Details | J6: Amount
A7: General insurance | B7: Total general insurance premiums collected and receivable (written) | H7: 1
B8: Less :
B9: (-) General insurance premiums cancelled | H9: 2
B10: (-) Re-insurance premiums issued to local parties | H10: 3
B11: (-) General re-insurance premiums issued to foreign parties | H11: 4
B12: Net general insurance premiums collected and earned | H12: 5 = 1 + 2 + 3 + 4 | I12: N/A
B13: Un-earned premiums reserve created at the end of the prior year | H13: 6
B14: Outstanding risks reserve created at the end of the prior year | H14: 7
B15: Total reserve for un-earned premiums and outstanding risks created during prior year | H15: 8 = 6 + 7
B16: The investment income of the non-resident companies engaged in activity through permanent establishment is determined as follows:
B17: Local general insurance premium written (A) | H17: 9
B18: General insurance international premiums (B) | H18: 10
B19: International investment revenue (C) | H19: 11
B20: Investment revenue as per above equation = (3) | H20: 12 = 9 + 10 + 11
B21: Any other income attributable to the permanent establishment(4) | H21: 13
B22: Total (5) = (1+2+3+4) | H22: 14 = 4 + 8 + 11 + 12
B23: Deduct:
B24: Compensation paid as per property or risk insurance policies in the Kingdom | H24: 15
B25: (-) amounts covered from re-insurance ( D) | H25: 16
B26: (=) Net compensation paid after excluding the amounts covered by re-insurance ( 6) | H26: 17 = 15 - 16
B27: Un-earned premiums reserve created at the end of the current year (7) | H27: 18
B28: Outstanding risks reserve created at the end of the current year (8) | H28: 19
B29: Permanent Establishment (PE) costs incurred in the Kingdom as per books (E) | H29: 20
B30: - Non-deductible expenses (item 11000) (F) | H30: 21
B31: = Deductible Permanent Establishment costs incurred in the Kingdom (9) | H31: 22 = 20 - 21
B32: Local general insurance premiums written (A) | H32: 23 = 9
B33: International General Insurance Premiums | H33: 24 = 10
B34: X Head office general and administrative expenses | H34: 25
B35: = PE's share of HO administrative and general expenses (10) | H35: 26 (= 23/24) x 25
B36: Total (11) = (6+7+8+9+10) | H36: 27 = 17 + 18 + 22 + 26
B37: Tax base as per Article (15)2 of the bye laws (12)= (5-11) | H37: 28 = 14 - 27
B38: Tax base as per worldwide Formula
B39: Local general Insurance premiums written | H39: 29 = 9
B40: ÷ Worldwide Saving Insurance Premiums | H40: 30 = 10
B41: X International investment Income | H41: 31
...

Sheet Payment schedule
A1: =IF(#REF!=0,"Zakat/Tax payer's Name:…………………..","Zakat/Tax payer's Name: "&#REF!) -> #REF!
A2: =IF(#REF!=0,"Unique No :","Unique No : "&RIGHT(#REF!,LEN(#REF!)-FIND(".",#REF!))) -> #REF!
A3: =IF(#REF!=0,"Year ended : ","Year ended :" &RIGHT(#REF!,LEN(#REF!)-5)) -> #REF!
A5: Settlements
A6: Receipt No. | B6: Type | C6: Date | D6: Amount
A19: Total | D19: =SUM(D7:D18) -> 0

Sheet Retained earnings
A1: Retained earnings movement during the year as per books
A2: Description | B2: Book balance of retained earnings at the beginning of the period | C2: Cash dividends distributed | D2: Transfer from/to a balance sheet item | H2: Profit/(Loss) for the year | I2: Book balance of retained earnings at the end of the period
D5: Reserves | E5: Partners' current account | F5: Capital | G5: Others
A6: 1 | B6: 2 | C6: 3 | D6: 4 | E6: 5 | F6: 6 | G6: 7 | H6: 8 | I6: 9= 2+3+ 4 + 5 + 6 + 7 + 8
A7: Saudi/GCC resident | I7: =SUM(B7:H7) -> 0
A8: Non-Saudi | I8: =SUM(B8:H8) -> 0
A9: Total | B9: =SUM(B7:B8) -> 0 | C9: =SUM(C7:C8) -> 0 | D9: =SUM(D7:D8) -> 0 | E9: =SUM(E7:E8) -> 0 | F9: =SUM(F7:F8) -> 0 | G9: =SUM(G7:G8) -> 0 | H9: =SUM(H7:H8) -> 0 | I9: =SUM(I7:I8) -> 0
A11: Opening balance | C11: =B9 -> 0
A12: Less: Dividend paid | C12: =C9 -> 0
A13: Addition to Zakat base | C13: =SUM(C11:C12) -> 0

Sheet Reserves
A1: Movement of reserves
A2: Name of reserve | B2: Balance of reserves at the beginning of the period | C2: Increase during the year | D2: Decrease during the year to increase the capital | E2: Adjustments | F2: Balance of reserves at the end of the period
A3: 1 | B3: 2 | C3: 3 | D3: 4 | E3: 5 | F3: 6=2+3-4+5
A4: Cash flow hedge reserve | F4: =B4+C4-D4+E4 -> 0
A5: Total | B5: =SUM(B4:B4) -> 0 | C5: =SUM(C4:C4) -> 0 | D5: =SUM(D4:D4) -> 0 | E5: =SUM(E4:E4) -> 0 | F5: =SUM(F4:F4) -> 0
A7: Opening share as per above | C7: =B5 -> 0
A8: Amount taken to as addition to zakat base for Saudi Shareholder | C8: =B5*#REF! -> #REF!

Sheet F.Shareholding
A1: Zakat/Tax payer's Name: Shuaibah Water and Electricity Company
A2: File No :
A3: Fiscal No : 3000013966
A4: Year ended : 31/12/2017
A6: Name
A8: - Direct ownership
A9: • Public Investment Fund | B9: =32% -> 0.32
A10: • Saudi Electricity Company excluding ARAMCO shares (93.07% x 8%) | B10: =(93.07%*8%) -> 0.074456
A12: - Indirect ownership
A13: • ACWA Through SAMAWEC (60% x 50% x 94.927%) | B13: =60%*50%*94.927% -> 0.284781
A15: Total Saudi Shareholding | B15: =SUM(B9:B14) -> 0.679237
A16: Non-Saudi shares and ownerhsip:
A17: • IFC through through indirect shareholding in SAMAWEC (60% x 50% x 5.073%) | B17: =60%*50%*5.073% -> 0.015219
A18: • Malaysian Shoaiba Consortium through direct ownership in Saudi Malaysia Water and Electricity Company (60% x 50%) | B18: =60%*50% -> 0.3
A19: •ARAMCO (6.93% x 8% ) | B19: =(6.93%*8%) -> 0.005544
A21: Total Non-Saudi shareholding | B21: =SUM(B17:B20) -> 0.320763
A23: Total ownership | B23: =B15+B21 -> 1

Sheet Declaration
C3: Are there any amendment in the ownership of the company or in the partners' shares in capital or profits? If yes, supporting documents and updated registration form to be attached. | I3: Yes No | K3: Specify
B4: Zakat payer declaration | C4: Is the weighted average method used for valuation of ending inventory (stock count)? | I4: Yes No | K4: Specify
C5: Is the lower of cost or market method is used for valuation of the ending inventory? | I5: Yes No | K5: Specify
C6: Are the statutory books maintained in Arabic? | I6: Yes No
C7: I declare that this return and its attachments are prepared per the books and records maintained by the entity for the fiscal period covered by this return and I shall be fully responsible in case it is proven that the information contained therein is incorrect.
C9: Name: | F9: Signature: | H9: Position: | J9: Company Stamp
B12: The CA certification | C12: I certify that the information recorded in the return are extracted from the taxpayer's books and records and are in accordance therewith, and that the return has been prepared according to the Saudi Income Tax Regulations.
C14: Name: | E14: License No. | G14: Financial No. | I14: Signature | K14: Stamp
B16: DIRECTIONS
B17: The department enables zakat/tax payers to benefit from the electronic services as per the following terms and conditions:
B18: 1 | C18: This Declaration is for zakat/tax payers who are assessed according to the regulations and instructions applicable at the Department of Zakat and Income Tax in respect of zakat collection and income tax regulations.
B19: 2 | C19: This declaration and its enclosures should be completed in Arabic, tax due paid within 120 days of end of the financial year, except for individuals companies, which should submit the return within 60 days of the financial year end.
B20: 3 | C20: Zakat / tax payer shall be fully responsible for authenticity of revenues and expenses and other information included in its return. In case of its inability to support the correctness of what stated in its return, the Department may, in addition to imposing any other statutory penalties, the department may disallow expenses not supported by the zakat / tax payer or the department may raise deemed assessment according to its view point in light of circumstances and facts related to the case and the information available to the department.
B21: 4 | C21: The declaration should include the results of the main and other secondary activities.
B22: 5 | C22: The declaration shall not be considered acceptable unless all of its fields are and all the required exhibits and schedules are duly completed.
B23: 6 | C23: The declaration will be considered submitted by way of official acknowledgement receipt issued by the Department in all electronic forms or official letters and settlement should be made accordingly.
B24: 7 | C24: All owned and existing activities information, in addition to the entity's address and contact details should be updated before submitting the return.
B25: 8 | C25: The monthly withholding tax return should be completed and submitted in accordance with Department's form within the first ten days of the month following the month in which the payment has been made to the beneficiary.
B26: 9 | C26: The withholder should complete and submit information related to withholding transactions for each financial year, as per the form prepared by the Department within not more than 120 days from end of the financial year, except for individuals companies, which should submit the return within 60 of the financial year.
B27: Acknowledgement with reading of instructions related to electronic returns service and their approval
