Workbook
Name _Toc255726701: #REF!
Name _Toc255726701: #REF!
Name _Toc255726701: #REF!
Name _Toc255726701: #REF!
Name _Toc255726701: #REF!
Name _Toc255726701: #REF!
Name _Toc255726701: #REF!
Name _Toc255726701: #REF!
Name _Toc255726701: #REF!

Sheet Cover
A14: 0
A15: (Foreign Company – Limited Liability Company)
A16: Riyadh – Kingdom of Saudi Arabia
A17: Financial Statements and Independent Auditor’s Report
A18: For the Year Ending 31 December 2024

Sheet Index
A1: =Cover!A14 -> 0
A2: =Cover!A15 -> (Foreign Company – Limited Liability Company) | J2: YEAR | K2: القوائم عن :
A3: =Cover!A16 -> Riyadh – Kingdom of Saudi Arabia
A4: ="FOR "&Index!J2&" "&" ENDED" -> FOR YEAR ENDED | F4: المقارن | G4: المقارن | I4: تاريخ الميزانية | J4: الى | K4: من | P4: period
A5: =H5& H6&H7 -> 31December2024 | F5: 01 | G5: 31 | H5: 31 | I5: يوم | J5: 31 | K5: 01 | P5: YEAR
F6: January | G6: December | H6: December | I6: شهر | J6: 12 | K6: 01
F7: 2017 | G7: 2023 | H7: 2024 | I7: عام | J7: 2024 | K7: 2024
I10: 4 | K10: المركز المالى
I11: 1 | K11: الدخل
I12: 1 | K12: حقوق الملكية
I13: 1 | K13: التدفقات
A14: Pages | C14: INDEX | I14: 1 | K14: سياسة 1
I15: 1 | K15: سياسة2
A16: 1-3 | C16: Independent auditor's report | I16: 1 | K16: سياسة3
A17: 4 | C17: Statement of financial position | K17: سياسة4
A18: 5 | C18: statement of profit or loss and other comprehensive income | K18: سياسة5
A19: 6 | C19: Statement of changes in equity | K19: سياسة6
A20: 7 | C20: Statement of cash flows | I20: 1 | K20: اصول ثابتة
A21: 8-18 | C21: Notes to the financial statements | I21: 1 | K21: ايضاحات مدينة
K22: ايضاحات مدينة2
I23: 1 | K23: راس المال
I24: 1 | K24: مخصصات
I25: 1 | K25: ايضاحات دائنة
I26: 1 | K26: ايراد و تكلفة
I27: 1 | K27: عمومية
I28: 1 | K28: عام
K30: فترة
K31: عام

Sheet Balance Sheet
A1: =Cover!A14 -> 0
A2: =Cover!A15 -> (Foreign Company – Limited Liability Company)
A3: =Cover!A16 -> Riyadh – Kingdom of Saudi Arabia
A4: ="Statement of financial position as at "&Index!A5 -> Statement of financial position as at 31December2024
A5: (saudi riyal)
D7: ="As at "&Index!G5&Index!G6 -> As at 31December | F7: ="As at "&Index!H5&Index!H6 -> As at 31December
D8: =Index!G7 -> 2023 | F8: =Index!H7 -> 2024 | H8: Note | M8: ASSETS
D10: =+A5 -> (saudi riyal) | F10: =+A5 -> (saudi riyal)
L11: Non-current assets
D12: =F!A15 -> 0 | F12: =F!C15 -> 0 | H12: 4 | K12: Property, plant and equipment
D13: =F!A46 -> 0 | F13: =F!C46 -> 0 | K13: Intangible assets
D14: =F!A55 -> 0 | F14: =F!C55 -> 0 | K14: Leasing Assets (net)
D15: =F!A64 -> 0 | F15: =F!C64 -> 0 | K15: Investment property
D16: =D!C13 -> 0 | F16: =D!E13 -> 0 | K16: Capital work in progress
D17: =D!C21 -> 0 | F17: =D!E21 -> 0 | K17: Investments in Subsidiaries
D18: =SUM(D12:D17) -> 0 | F18: =SUM(F12:F17) -> 0 | K18: Total non-current assets
I20: إيضاح | L20: Current assets
D21: =D!C29 -> 0 | F21: =D!E29 -> 0 | K21: Inventories
D22: =D!C38 -> 0 | F22: =D!E38 -> 0 | H22: 5 | K22: Trade receivables
D23: =D!C50 -> 0 | F23: =D!E50 -> 0 | H23: 6 | K23: Prepayments and other receivables
D24: =L!D21 -> 0 | F24: =+L!H21 -> 0 | H24: 9 | K24: Related parties
D25: =D!C58 -> 0 | F25: =D!E58 -> 0 | H25: 14 | K25: Short term investments
D26: =D!C66 -> 0 | F26: =D!E66 -> 0 | H26: 7 | I26: 1 | K26: Cash and cash equivalents
D27: =SUM(D21:D26) -> 0 | F27: =SUM(F21:F26) -> 0 | K27: Total current assets
D28: =D18+D27 -> 0 | F28: =F18+F27 -> 0 | K28: TOT AL ASSETS
M30: EQUITY AND LIABILITIES
K31: Equity
D32: ='Partners Equity'!F20 -> 0 | F32: ='Partners Equity'!F27 -> 0 | H32: 8 | K32: capital
D33: ='Partners Equity'!E20 -> 0 | F33: ='Partners Equity'!E27 -> 0 | K33: Statutory reserve
D34: ='Partners Equity'!D20 -> 0 | F34: ='Partners Equity'!D27 -> 0 | K34: additional capital
D35: ='Partners Equity'!C20 -> 0 | F35: ='Partners Equity'!C27 -> 0 | K35: Accumulated losses
D36: =SUM(D32:D35) -> 0 | F36: =SUM(F32:F35) -> 0 | K36: Total equity
K38: Non-current liabilities
D39: =L!E21 -> 0 | F39: =L!I21 -> 0 | H39: 9 | K39: Credit Related parties
D40: =+'C'!D14 -> 0 | F40: =+'C'!F14 -> 0 | H40: 10 | K40: Provision for Employees' benefits
D41: ='C'!D45 -> 0 | F41: 0 | H41: 19 | K41: Long-term leasing creditors
D42: ='C'!D46 -> 0 | F42: 0 | H42: 19 | K42: Deferred income
D43: =SUM(D39:D42) -> 0 | F43: =SUM(F39:F42) -> 0 | K43: Total Non-current liabilities
K44: current liabilities
D45: ='C'!D66 -> 0 | F45: ='C'!F66 -> 0 | H45: 11 | K45: Trade payables
...

Sheet Income Statement
A1: =Cover!A14 -> 0
A2: =Cover!A15 -> (Foreign Company – Limited Liability Company)
A3: =Cover!A16 -> Riyadh – Kingdom of Saudi Arabia
A4: ="statement of profit or loss and other comprehensive income For year "&Index!A5 -> statement of profit or loss and other comprehensive income For year 31December2024
A5: ='Balance Sheet'!A5:M5 -> (saudi riyal)
B7: prieod from 5 may to 31 december | D7: For the Period Ended 31 December 2024 | F7: Note
B8: ='Balance Sheet'!$D$10 -> (saudi riyal) | D8: ='Balance Sheet'!$F$10 -> (saudi riyal)
B10: =S!C18 -> 0 | D10: =S!E18 -> 0 | F10: 14 | G10: Revenue
B12: =-S!C27 -> 0 | D12: =-S!E27 -> 0 | F12: 15 | G12: Cost of Revenue
B13: =SUM(B10:B12) -> 0 | D13: =SUM(D10:D12) -> 0 | G13: OPERATING PROFIT
B15: =-S!C35 -> 0 | D15: 0 | F15: 15 | G15: Selling and distribution expenses
B16: =-G!B24 -> 0 | D16: =-G!D24 -> 0 | F16: 16 | G16: General and administrative expenses
B17: =SUM(B15:B16) -> 0 | D17: =SUM(D15:D16) -> 0 | G17: Total Expenses
B18: =B13+B17 -> 0 | D18: =D13+D17 -> 0 | F18: Income for Operating process
B19: 0 | D19: 0 | G19: Gain (loss) on sale of property, plant and equipment
B20: 0 | D20: 0 | G20: financing costs
B21: =SUM(B18:B20) -> 0 | D21: =SUM(D18:D20) -> 0 | G21: INCOME BEFORE income tax
B22: =-P!B36 -> 0 | D22: =-P!D36 -> 0 | F22: 13 | G22: income tax
B23: =SUM(B21:B22) -> 0 | D23: =SUM(D21:D22) -> 0 | G23: NET INCOME FOR THE YEAR
B27: 0 | D27: 0 | G27: Other comprehensive income item:
B29: =SUM(B23:B28) -> 0 | D29: =SUM(D23:D28) -> 0 | G29: TOTAL COMPREHENSIVE INCOME
A37: ='Balance Sheet'!A65 -> The accompanying form integral part of these financial statements.
A38: ="-"&SUM(Index!I10:I11)&"-" -> -5-

Sheet Partners Equity
B1: =Cover!A14 -> 0
B2: =Cover!A15 -> (Foreign Company – Limited Liability Company)
B3: =Cover!A16 -> Riyadh – Kingdom of Saudi Arabia
B4: ="Statement of changes in equity For period from 13 march to "&Index!A5 -> Statement of changes in equity For period from 13 march to 31December2024
B6: Total | C6: ='Balance Sheet'!K35 -> Accumulated losses | D6: additional capital | E6: ='Balance Sheet'!K33 -> Statutory reserve | F6: ='Balance Sheet'!K32 -> capital
B7: ='Balance Sheet'!A5 -> (saudi riyal) | C7: ='Balance Sheet'!$A$5 -> (saudi riyal) | D7: ='Balance Sheet'!$A$5 -> (saudi riyal) | E7: ='Balance Sheet'!$A$5 -> (saudi riyal) | F7: ='Balance Sheet'!$A$5 -> (saudi riyal)
B8: =SUM(C8:F8) -> 0 | C8: 0 | D8: 0 | E8: 0 | F8: 0 | G8: Balance in 05 may 2018
B9: =SUM(C9:F9) -> 0 | C9: 0 | D9: 0 | E9: 0 | F9: 0 | G9: additional capital
B10: =SUM(C10:F10) -> 0 | C10: 0 | D10: 0 | E10: 0 | F10: 0 | G10: Balance in 01 january 2022
B11: =SUM(C11:F11) -> 0 | C11: ='Income Statement'!B23 -> 0 | D11: 0 | E11: 0 | F11: 0 | G11: Net income for the year after zakat
B12: =SUM(C12:F12) -> 0 | C12: 0 | D12: 0 | E12: 0 | F12: 0 | G12: capital increase
B13: 0 | C13: 0 | D13: 0 | E13: 0 | F13: 0 | G13: settlements | I13: فرق
B14: =SUM(C14:F14) -> 0 | C14: 0 | D14: 0 | E14: 0 | F14: 0 | G14: additional contributions to capital | I14: فرق
G15: Net income for the year
G16: Capital increase
G17: Other comprehensive income
B18: =SUM(C18:F18) -> 0 | C18: =SUM(C10:C14) -> 0 | D18: =SUM(D10:D14) -> 0 | E18: =SUM(E10:E14) -> 0 | F18: 0 | G18: Balance at 31 December 2022
B20: =SUM(C20:F20) -> 0 | C20: 0 | D20: =+D18 -> 0 | E20: =+E18 -> 0 | F20: 0 | G20: Balance in 01 january 2023
B21: 0 | C21: 0 | D21: 0 | E21: 0 | F21: 0 | G21: capital increase
B22: 0 | C22: 0 | D22: 0 | E22: 0 | F22: 0 | G22: settlements
B23: =SUM(C23:F23) -> 0 | C23: 0 | D23: 0 | E23: 0 | F23: 0 | G23: additional contributions to capital
B24: =SUM(C24:F24) -> 0 | C24: ='Income Statement'!D23 -> 0 | D24: 0 | E24: 0 | F24: 0 | G24: =IF(C24>=0,"Net income for the year","Net Loss for the year") -> Net income for the year
B25: =SUM(C25:F25) -> 0 | C25: 0 | D25: 0 | E25: 0 | F25: 0 | G25: Capital increase
B26: =SUM(C26:F26) -> 0 | C26: ='Income Statement'!D27 -> 0 | D26: 0 | E26: 0 | F26: 0 | G26: Other comprehensive income
B27: =SUM(C27:F27) -> 0 | C27: =SUM(C20:C26) -> 0 | D27: =SUM(D20:D26) -> 0 | E27: =SUM(E20:E26) -> 0 | F27: =SUM(F20:F26) -> 0 | G27: Balance at 31 December 2023 | I27: =+B27-'Balance Sheet'!F36 -> 0
B29: *The additional capital represents: support from related parties to the company and they have waived all these amounts in favor of the company as support in exchange for expansion and spread, and this waiver does not require any rights or obligations on the company.
A33: ='Balance Sheet'!A65 -> The accompanying form integral part of these financial statements.
A34: ="-"&SUM(Index!I10:I12)&"-" -> -6-

Sheet Cash Flow
A1: =Cover!A14 -> 0
A2: =Cover!A15 -> (Foreign Company – Limited Liability Company)
A3: =Cover!A16 -> Riyadh – Kingdom of Saudi Arabia
A4: ="Statement of cash flows For prieod Ended"&Index!A5 -> Statement of cash flows For prieod Ended31December2024
A5: ='Balance Sheet'!A5 -> (saudi riyal)
B7: ='Income Statement'!$B$7 -> prieod from 5 may to 31 december | D7: =+'Income Statement'!$D$7 -> For the Period Ended 31 December 2024 | J7: :Cash flow from operating activities
B8: ='Balance Sheet'!$D$10 -> (saudi riyal) | D8: ='Balance Sheet'!$F$10 -> (saudi riyal)
B10: ='Income Statement'!B21 -> 0 | D10: ='Income Statement'!D21 -> 0 | I10: ='Income Statement'!G21 -> INCOME BEFORE income tax
J11: Adjustment to reconcile income before zakat to net cash
B12: 0 | D12: 0 | I12: Adjustment about prievious years
I13: :provided by operating activities
B14: 0 | D14: =F!I15 -> 0 | I14: Depreciation of property, plant and equipment
B15: =-'Income Statement'!B19 -> 0 | D15: =-'Income Statement'!D19 -> 0 | I15: Gain on disposal of property, plant and equipment
B16: 0 | D16: ='C'!F12 -> 0 | I16: Employees' benefits
J17: :Working capital changes
B18: 0 | D18: =D!C36-D!E36 -> 0 | I18: ='Balance Sheet'!K22 -> Trade receivables
B19: 0 | D19: ='Balance Sheet'!D21-'Balance Sheet'!F21 -> 0 | I19: ='Balance Sheet'!K21 -> Inventories
B20: 0 | D20: =+'Balance Sheet'!D23-'Balance Sheet'!F23 -> 0 | I20: ='Balance Sheet'!K23 -> Prepayments and other receivables
B21: 0 | D21: =+'Balance Sheet'!F45-'Balance Sheet'!D45 -> 0 | I21: ='Balance Sheet'!K45 -> Trade payables
B22: 0 | D22: =+'Balance Sheet'!F46-'Balance Sheet'!D46 -> 0 | I22: ='Balance Sheet'!K46 -> Accruals and other payables
B23: 0 | D23: ='C'!F13 -> 0 | I23: Employees' benefits paid
B24: 0 | D24: =P!D37+P!D35 -> 0 | I24: Zakat paid
B25: =SUM(B10:B24) -> 0 | D25: =SUM(D10:D24) -> 0 | H25: Net cash used in operating activities
J27: CASH FLOWS FROM INVESTING ACTIVITIES
B28: 0 | D28: =+F!O15-F!G15+'Income Statement'!D19 -> 0 | I28: Additions to property, plant and equipment
B29: 0 | D29: =-F!Q15-F!Q55 -> 0 | I29: Purchase of real estate, machinery and equipment
B30: 0 | D30: =-F!Q16-F!Q56 -> 0 | I30: ='Balance Sheet'!K16 -> Capital work in progress
B31: =SUM(B28:B30) -> 0 | D31: =SUM(D28:D30) -> 0 | H31: Net cash generated from investing activities
J33: CASH FLOWS FROM FINANCING ACTIVITIES
D34: ='Partners Equity'!F21 -> 0 | I34: ='Partners Equity'!F6 -> capital
B35: 0 | D35: ='Partners Equity'!D23 -> 0 | I35: ='Partners Equity'!D6 -> additional capital
B36: 0 | D36: ='Balance Sheet'!F39-'Balance Sheet'!D39 -> 0 | I36: ='Balance Sheet'!K24 -> Related parties
B37: 0 | D37: ='Partners Equity'!C22 -> 0 | I37: coverage of previous years' losses
B38: =SUM(B36:B37) -> 0 | D38: =SUM(D34:D37) -> 0 | I38: Net cash generated from financing activities
B40: =B38+B31+B25 -> 0 | D40: =D38+D31+D25 -> 0 | E40: Net Change in cash and cash equivalents
B41: 0 | D41: =+B42 -> 0 | H41: Cash and cash equivalents at the beginning of the year
B42: =SUM(B40:B41) -> 0 | D42: =SUM(D40:D41) -> 0 | H42: Cash and cash equivalents at the end of the year
A55: ='Balance Sheet'!A65 -> The accompanying form integral part of these financial statements.
A56: ="-"&SUM(Index!I10:I13)&"-" -> -7-
B59: =B42-'Balance Sheet'!D26 -> 0 | D59: =D42-'Balance Sheet'!F26 -> 0

Sheet 1
B1: =Cover!A14 -> 0
B2: =Cover!A15 -> (Foreign Company – Limited Liability Company)
B3: =Cover!A16 -> Riyadh – Kingdom of Saudi Arabia
B4: ="NOTES TO THE FINANCIAL STATEMENTS FOR PERIOD ENDED"&Index!A5 -> NOTES TO THE FINANCIAL STATEMENTS FOR PERIOD ENDED31December2024
B5: ='Balance Sheet'!A5 -> (saudi riyal)
H8: General | J8: -1
A9: Name of company: 00000000000000
A10: Legal entity: (Foreign Company - Limited Liability)
B11: Commercial Register: 00000000000000000000000000
B13: The principal activities : 00000000000000000000000000000000000000000000000
C14: City | D14: Register Date | F14: Register No | H14: Branches
D15: 10/12/1417 h
B19: Financial year: 0000000000000000000000000000
H20: Basics of preparing financial statements: | J20: -2
I22: Applicable accounting standards: | J22: 2-1
B23: The financial statements have been prepared in accordance with the International Financial Reporting Standard for Small and Medium-sized Enterprises approved in the Kingdom of Saudi Arabia and other standards and issuances approved by the Saudi Organization for Auditors and Accountants, and the facility has fully complied with the sections of the International Financial Reporting Standard and those related issuances and standards.
H25: Basis of measurement | J25: 2-2
A26: The attached financial statements have been prepared on the basis of historical cost and according to the accrual principle of accounting, and in accordance with the International Standard for Financial Reporting for Small and Medium-Sized Enterprises approved by the Saudi Organization for Auditors and Accountants.
E27: Presentation currency of the financial statements | J27: 2-3
B28: The financial statements have been prepared on the historical cost convention except for the defined benefit obligation which is recognized at the present value of future obligation using the projected unit credit method. | J28: (A
E31: Foreign currency transactions and balances | J31: B)
C32: Transactions in foreign currencies are translated into Saudi riyals at the exchange rates prevailing on the date of those transactions. The gains and losses of currency differences resulting from the settlement of such transactions, as well as resulting from the translation of monetary assets and liabilities in foreign currency based on the prevailing currency exchange rates as at the end of the period, are recorded in the income statement.
E34: A summary of significant accounting policies: | J34: -3
E36: Accounting estimates and assumptions | J36: 3-2
B37: Preparing financial statements in accordance with the International Financial Reporting Standard for Small and Medium-sized Enterprises requires the use of estimates and assumptions that affect the amounts of assets and liabilities, disclosure of potential assets and liabilities as at the date of the financial statements, as well as estimating the amounts of revenues and expenses during the financial period. Estimates and assumptions are continually evaluated and are based on past experience and other factors, including expectations of future events that are considered appropriate in the circumstances. The entity makes estimates and assumptions about the future that, by definition, will seldom equal the actual results.
H40: Property, plant and equipment | J40: 3-3
B41: Property, plant and equipment are recognized at cost less accumulated depreciation. The cost includes the amount paid for the acquisition of the asset and any costs directly attributable to bringing the asset to operation on site and in the condition necessary for it to be operable in the manner intended by the administration. These may include site setup, delivery, initial handling, installation, assembly and operating testing. To be carried out using the straight-line method over the estimated period of their useful life using the following annual rates:
C44: Dep Rate | E44: Asset | F44: Dep Rate | H44: Asset
C45: 0.15 | E45: =F!U14 -> 0 | F45: 0.15 | H45: Furniture
C46: 0.15 | E46: machinery and equipment | F46: 0.15 | H46: computer
F47: 0.15 | H47: Electrical appliance
C49: An entity recognizes the carrying amount of property, plant and equipment or recognizes as a separate asset the cost of replacing parts of this item when the cost is incurred and when future economic benefits are probable. The replacement value of the replaced part is written off. | J49: *
C51: The entity applies the cost model to measure all classes of property and equipment. After recognition as an asset, an item of property and equipment is stated at cost less any amortized depreciation and impairment losses, if any. | J51: *
B62: ="-"&SUM(Index!I10:I14)&"-" -> -8-

Sheet 2 
A1: =Cover!A14 -> 0
A2: =Cover!A15 -> (Foreign Company – Limited Liability Company)
A3: =Cover!A16 -> Riyadh – Kingdom of Saudi Arabia
A4: ='1'!B4 -> NOTES TO THE FINANCIAL STATEMENTS FOR PERIOD ENDED31December2024
A5: ='Balance Sheet'!A5 -> (saudi riyal)
H7: Intangible assets
A9: Intangible assets comprise of ......................., Intangible assets with finite useful lives that are acquired separately are carried at cost less accumulated amortization and accumulated impairment losses. Amortization is recognized on a straight-line basis over their estimated useful lives of ................years respectively. The estimated useful life and amortization method are reviewed at the end of each reporting period, with the effect of any changes in estimate being accounted for on a prospective basis. Intangible assets with indefinite useful lives that are acquired separately are carried at cost less accumulated impairment losses.
H16: investment properties
A18: An enterprise is classified as an investment property if the purpose of retaining the asset is to earn rental income or to develop capital Or both, and are measured at cost, including expenses directly related to the acquisition of the investment property .The cost model used in Section 17 of the (SMEs) where accumulated depreciation and accumulated impairment losses are subtracted If any, because it is impossible to measure what will result from measuring its fair value in a reliable and cost-effective manner.
J23: *
J25: *
H26: Financial assets and liabilities | K26: 3-
J28: Frist measurement | K28: 3-5
J30: Financial assets and liabilities are classified as follows:
J32: Cash and cash equivalents | K32: *
J33: held-to-maturity investments | K33: *
J34: Financial assets available for sale | K34: *
A35: receivables and credit (including trade receivables, short-term investments, cash and cash equivalents). | K35: *
A36: A financial asset or a financial liability is initially recognized at the transaction price including transaction costs except for the initial measurement of financial assets and liabilities subsequently measured at fair value through profit or loss.
J39: Subsequent measurement | K39: 3-6
A41: Debt instruments classified as current assets or current liabilities are measured at the undiscounted amount of cash or other cash consideration expected to be paid or received Arrangement(Unless, in fact, the arrangement constitutes a financing transaction)
J45: Inventories
A46: Inventories are stated at the lower of cost and net estimated sales value. Costs of inventories are determined on a weighted average cost basis. net estimated sales represents the estimated selling price for inventories less all estimated costs of completion and costs necessary to make the sale and markdown. A provision is made against slow moving, obsolete and damaged inventories. Damaged inventories are identified during the inventory count. Provision for slow moving and obsolete inventories is assessed periodically by management for each inventory category as part of its ongoing financial reporting review.
J51: Investments in associate companies | K51: 3-7
B52: An associate is an entity, including an entity that is not legally independent such as a partnership, over which the investing entity has significant influence.Which is not a subsidiary or a stake in a joint venture.Significant influence is the ability to participate in the financial and operating policy decisions of the investee, but is not control or control Common to those policies, and they are accounted for at cost minus any accumulated impairment losses.
J54: government grants | K54: 3-8
B55: Government grants prove as follows:
C56: Grants that do not impose on the entity certain conditions relating to future performance are recognized in income when this grant becomes owed to the facility | K56: (a)
B57: Grants that impose on the entity certain conditions relating to future performance are recognized in income only when the performance conditions are met. | K57: (b)
B58: The grants obtained by the facility before the revenue recognition criteria are met, are recorded as an obligation An entity measures government grants at the fair value of the assets received or receivable. | K58: (c)
H62: Borrowing costs | K62: 3-9
B63: The entity recognizes all borrowing costs as an expense in profit or loss in the period in which they are incurred. Using The effective interest rate method for financial obligations that are not at fair value through profit or loss.
H64: Accounts payable and accruals
B65: The amount of the liability to be paid for goods and services received is recognized whether or not the entity is invoiced .
H67: Provisions | K67: 3-10
B68: Provisions are recognized when the Company has a present obligation (legal or constructive) as a resultof a past event, it is probable that an outflow of resources embodying economic benefits will be required to settle the obligation and a reliable estimate can be made of the amount of the obligation.
H69: income tax | K69: 3-11
B70: The income tax is accounted for in the attached financial statements by charging it to the income statement. Any adjustments that may arise from the final tax assessment are recorded in the income statement in the year the assessment is finalized.
J73: Government Grants
K75: Government grants are as follows:
...

Sheet 3
B1: =Cover!A14 -> 0
B2: =Cover!A15 -> (Foreign Company – Limited Liability Company)
B3: =Cover!A16 -> Riyadh – Kingdom of Saudi Arabia
B4: ='1'!B4 -> NOTES TO THE FINANCIAL STATEMENTS FOR PERIOD ENDED31December2024
B5: ='Balance Sheet'!A5 -> (saudi riyal)
J7: Summary of significant accounting policies - continued: | K7: 3-
J8: Employee Benefits - Provision for end of service | K8: 3-12
B9: Under the terms of the labor and labor regulations in Saudi Arabia, the provision for employees' end of service indemnity is recognized by the entity and the expense is charged to the statement of income. The amount of the liability is calculated on the basis of the present value of the earned remuneration due to the employee if the employee leaves his employment as of the statement of financial position date, The amounts paid at the end of service are calculated on the basis of the salaries and allowances of the last employees and the number of years of their accumulated service as described in the labor regulations and workers within the Kingdom of Saudi Arabia. As the measurement of present value and actuarial assumptions will result from undue effort and cost, the actuarial assumptions of the discount rate, retirement age, salary increase and settlement have been disregarded in the period in which they are incurred.
H10: Statutory reserve | K10: 3-13
B11: In accordance with the regulations for companies in the kingdom of Saudi Arabia and the Company's articles of association. the Company established a statutory reserve by the appropriation of 10% of net income until the reserve equaled 30% of the share capital
H12: Revenue recognition | K12: 3-14
B13: Revenues consist of the fair values ​​of the consideration received or receivable from the sale of goods and services within the normal course of an enterprise's business and revenue is recognized when the following conditions are :
B14: 1 - The possibility of reliable measurement of revenue. 2 -The economic benefit is likely to be incurred by the enterprise. 3 - the entity shall not retain the right of continuing administrative intervention to the extent that it is normally associated with ownership. 4 - the possibility of measuring the cost of business operations and the costs of completion of sales related to it reliably. 5 -The entity shall transfer the significant risks and rewards of ownership of the goods to the buyer .
H15: Cost of revenue | K15: 3-15
B16: The cost of revenue from cash and Deferred purchases consists of goods, services, selling and marketing expenses. Other expenses other than the cost of services are classified as administrative and general expenses. Expenses are recorded when incurred as a period expense if the beneficiary periods can not be determined and are charged to the relevant periods.
H17: Operating and financing leases | K17: 3-16
B18: Lease contracts are classified as finance leases if the lease results in a material transfer of the interest and the related term of the lease. Other leases are classified as operating leases where the operating income is recognized in the statement of income on a straight-line basis over the lease term.
H20: General and administrative expenses | K20: 3-17
B21: Administrative and general expenses include direct and indirect costs that are not specifically related to the cost of revenue under the IFRS for SMEs. These costs shall be divided between the cost of income and administrative and general expenses, if necessary, in a systematic manner in accordance with the expense function.
H22: foreign currency
H23: Presentation currency of financial statements | K23: a)
B24: Items in these financial statements are presented in Saudi Riyal ("SAR"), which is the functional currency of the presentation of the financial statements of the entity.
H26: Transactions and balances | K26: b)
B27: Transactions denominated in foreign currencies are translated into Saudi Riyals at the rates of exchange ruling at the date of the transactions. Foreign currency gains and losses resulting from the settlement of such transactions and from the translation of monetary assets and liabilities denominated in foreign currencies are recognized at the rates prevailing at the end of the period in the statement of income.
B35: ="-"&SUM(Index!I10:I16)&"-" -> -10-

Sheet 4
A1: =Cover!A14 -> 0
A2: =Cover!A15 -> (Foreign Company – Limited Liability Company)
A3: =Cover!A16 -> Riyadh – Kingdom of Saudi Arabia
A4: ='1'!B4 -> NOTES TO THE FINANCIAL STATEMENTS FOR PERIOD ENDED31December2024
A5: ='Balance Sheet'!A5 -> (saudi riyal)
P7: 3- First-time adoption of SMEs :
P9: 3-1 The following is a reconciliation of the Company's statement of financial position reported in accordance with SOCPA to
P10: its statement of financial position under SMEs
D11: 01January2017 | J11: 31DECEMBER2017
B13: SMEs | D13: impact of conversion | F13: SOCPA | H13: SMEs | J13: impact of conversion | L13: SOCPA | M13: Note
P14: Non-current assets
B15: =+F15+D15 -> 4810396 | D15: 0 | F15: 4810396 | H15: =+L15+J15 -> 3660315 | J15: 0 | L15: 3660315 | P15: Property, plant and equipment
B16: =+F16+D16 -> 0 | D16: 0 | F16: 0 | H16: =+L16+J16 -> 0 | J16: 0 | L16: 0 | P16: Intangible assets
B17: =+F17+D17 -> 0 | D17: 0 | F17: 0 | H17: =+L17+J17 -> 0 | J17: 0 | L17: 0 | P17: Leasing Fixed Assets (net)
B18: =+F18+D18 -> 0 | D18: 0 | F18: 0 | H18: =+L18+J18 -> 0 | J18: 0 | L18: 0 | P18: Investment property
B19: =+F19+D19 -> 113674 | D19: 0 | F19: 113674 | H19: =+L19+J19 -> 136120 | J19: 0 | L19: 136120 | P19: Construction work in progress
B20: =+F20+D20 -> 0 | D20: 0 | F20: 0 | H20: =+L20+J20 -> 0 | J20: 0 | L20: 0 | P20: Investments in associates
B21: =SUM(B15:B20) -> 4924070 | D21: =SUM(D15:D20) -> 0 | F21: =SUM(F15:F20) -> 4924070 | H21: =SUM(H15:H20) -> 3796435 | J21: =SUM(J15:J20) -> 0 | L21: =SUM(L15:L20) -> 3796435 | P21: Total non-current assets
P23: Current assets
B24: =+F24+D24 -> 3622948 | D24: 0 | F24: 3622948 | H24: =+L24+J24 -> 3557557 | J24: 0 | L24: 3557557 | P24: Inventories
B25: =+F25+D25 -> 0 | D25: 0 | H25: =+L25+J25 -> 0 | J25: 0 | P25: Trade receivables
B26: =+F26+D26 -> 188703 | D26: 0 | F26: 188703 | H26: =+L26+J26 -> 210297 | J26: 0 | L26: 210297 | P26: Prepayments and other receivables
B27: =+F27+D27 -> 0 | D27: 0 | H27: =+L27+J27 -> 0 | J27: 0 | P27: Debit Related parties
B28: =+F28+D28 -> 0 | D28: 0 | H28: =+L28+J28 -> 0 | J28: 0 | P28: Short term investments
B29: =+F29+D29 -> 13799 | D29: 0 | F29: 13799 | H29: =+L29+J29 -> 44504 | J29: 0 | L29: 44504 | P29: Cash and cash equivalents
B30: =SUM(B24:B29) -> 3825450 | D30: =SUM(D24:D29) -> 0 | F30: =SUM(F24:F29) -> 3825450 | H30: =SUM(H24:H29) -> 3812358 | J30: =SUM(J24:J29) -> 0 | L30: =SUM(L24:L29) -> 3812358 | P30: Total current assets
B31: =B21+B30 -> 8749520 | D31: =D21+D30 -> 0 | F31: =F21+F30 -> 8749520 | H31: =H21+H30 -> 7608793 | J31: =J21+J30 -> 0 | L31: =L21+L30 -> 7608793 | P31: TOT AL ASSETS
P33: EQUITY AND LIABILITIES
P34: Equity
B35: =+F35+D35 -> 10000000 | D35: 0 | F35: 10000000 | H35: =+L35+J35 -> 10000000 | J35: 0 | L35: 10000000 | P35: capital
B36: =+F36+D36 -> 0 | D36: 0 | H36: =+L36+J36 -> 0 | J36: 0 | P36: Statutory reserve
B37: =+F37+D37 -> -7784438 | D37: 0 | F37: -7784438 | H37: =+L37+J37 -> -10509615 | J37: -2325 | L37: -10507290 | M37: 3-A | P37: Accumulated losses
B38: =SUM(B35:B37) -> 2215562 | D38: =SUM(D35:D37) -> 0 | F38: =SUM(F35:F37) -> 2215562 | H38: =SUM(H35:H37) -> -509615 | J38: =SUM(J35:J37) -> -2325 | L38: =SUM(L35:L37) -> -507290 | P38: Total equity
P40: Non-current liabilities
B41: =+F41+D41 -> 6393646 | D41: 0 | F41: 6393646 | H41: =+L41+J41 -> 7767073 | J41: 0 | L41: 7767073 | P41: Credit Related parties
B42: =+F42+D42 -> 25451 | D42: 0 | F42: 25451 | H42: =+L42+J42 -> 75374 | J42: 0 | L42: 75374 | P42: Provision for Employees' benefits
B43: =+F43+D43 -> 0 | D43: 0 | F43: 0 | H43: =+L43+J43 -> 0 | J43: 0 | L43: 0 | P43: Long-term leasing creditors
B44: =SUM(B41:B43) -> 6419097 | D44: =SUM(D41:D43) -> 0 | F44: =SUM(F41:F43) -> 6419097 | H44: =SUM(H41:H43) -> 7842447 | J44: =SUM(J41:J43) -> 0 | L44: =SUM(L41:L43) -> 7842447 | P44: Total Non-current liabilities
P45: current liabilities
B46: =+F46+D46 -> 0 | D46: 0 | F46: 0 | H46: =+L46+J46 -> 0 | J46: 0 | L46: 0 | P46: Trade payables
...

Sheet 5
A1: =Cover!A14 -> 0
A2: =Cover!A15 -> (Foreign Company – Limited Liability Company)
A3: =Cover!A16 -> Riyadh – Kingdom of Saudi Arabia
A4: ='1'!B4 -> NOTES TO THE FINANCIAL STATEMENTS FOR PERIOD ENDED31December2024
A5: ='Balance Sheet'!A5 -> (saudi riyal)
M7: 3- First-time adoption of SMEs : | Q7: =104425+406648 -> 511073
F9: 31DECEMBER2017
B11: SMEs | D11: Re classification | F11: impact of conversion | H11: SOCPA | J11: Note
B12: =+H12+F12+D12 -> 175462 | D12: 0 | F12: 0 | H12: 175462 | M12: Revenue
B14: =+H14+F14+D14 -> -870214 | D14: -714768 | F14: 0 | H14: -155446 | M14: Cost of Revenue
B15: =SUM(B14+B12) -> -694752 | D15: =SUM(D14+D12) -> -714768 | F15: =SUM(F14+F12) -> 0 | H15: =SUM(H14+H12) -> 20016 | M15: OPERATING PROFIT
B17: =+H17+F17+D17 -> 0 | D17: 0 | F17: 0 | H17: 0 | M17: Selling and distribution expenses
B18: =+H18+F18+D18 -> -2015442 | D18: -435313 | F18: -2325 | H18: =-1577804 -> -1577804 | J18: 3-A 3-B | M18: General and administrative expenses
B19: =+H19+F19+D19 -> 0 | D19: 1150081 | F19: 0 | H19: -1150081 | J19: 3-B | M19: depreciacion
B20: =+H20+F20+D20 -> 0 | D20: 0 | F20: 0 | H20: 0 | M20: Financing expenses
B21: =SUM(B17:B20) -> -2015442 | D21: =SUM(D17:D20) -> 714768 | F21: =SUM(F17:F20) -> -2325 | H21: =SUM(H17:H20) -> -2727885 | M21: Total Expenses
B23: =+H23+F23+D23 -> 0 | D23: 0 | F23: 0 | H23: 0 | M23: Gain on disposal of property, plant and equipment
B24: =+H24+F24+D24 -> 0 | D24: 0 | F24: 0 | H24: 0 | M24: Other income
B25: =+B15+B21+B23+B24 -> -2710194 | D25: =+D15+D21+D23+D24 -> 0 | F25: =+F15+F21+F23+F24 -> -2325 | H25: =+H15+H21+H23+H24 -> -2707869 | M25: INCOME BEFORE ZAKAT
B26: =+H26+F26+D26 -> -14983 | D26: 0 | F26: 0 | H26: -14983 | M26: Zakat
B27: =SUM(B25:B26) -> -2725177 | D27: =SUM(D25:D26) -> 0 | F27: =SUM(F25:F26) -> -2325 | H27: =SUM(H25:H26) -> -2722852 | M27: NET INCOME FOR THE YEAR
M28: Other comprehensive income item:
B30: =+H30+F30+D30 -> 0 | D30: 0 | F30: 0 | H30: 0
B31: =+H31+F31+D31 -> 0 | D31: 0 | F31: 0 | H31: 0
B32: =SUM(B27:B31) -> -2725177 | D32: =SUM(D27:D31) -> 0 | F32: =SUM(F27:F31) -> -2325 | H32: =SUM(H27:H31) -> -2722852 | M32: TOTAL COMPREHENSIVE INCOME
A34: Adjustment of professional fees due for an increase of SR 2,325 as accrued expenses and administrative expenses not recognized in 2017 in accordance with Section 10, "Accounting Policies, Estimates and Errors" of SMEs. | M34: 3-A
A37: Reclassification of depreciation and presentation of fixed assets based on the expense function in accordance with Section 5 "Income statement and comprehensive income" of SMEs. | M37: 3-B
A41: ="-"&SUM(Index!I10:I18)&"-" -> -10-

Sheet 6
B1: =Cover!A14 -> 0
B2: =Cover!A15 -> (Foreign Company – Limited Liability Company)
B3: =Cover!A16 -> Riyadh – Kingdom of Saudi Arabia
B4: ='1'!B4 -> NOTES TO THE FINANCIAL STATEMENTS FOR PERIOD ENDED31December2024
B5: ='Balance Sheet'!A5 -> (saudi riyal)
B53: ="-"&SUM(Index!I10:I19)&"-" -> -10-

Sheet F
A1: =Cover!A14 -> 0
A2: =Cover!A15 -> (Foreign Company – Limited Liability Company)
A3: =Cover!A16 -> Riyadh – Kingdom of Saudi Arabia
A4: ='1'!B4 -> NOTES TO THE FINANCIAL STATEMENTS FOR PERIOD ENDED31December2024
A5: ='Balance Sheet'!A5 -> (saudi riyal)
S8: ='Balance Sheet'!K12 -> Property, plant and equipment | V8: ='Balance Sheet'!H12&"-" -> 4-
U9: =" Property, plant and equipment AS at" &" " &Index!$H$5&" "&Index!$H$6&":" -> Property, plant and equipment AS at 31 December:
A11: Net book amounts | C11: Net book amounts | E11: Accum depreciation | G11: Disposals | I11: depreciation | K11: Accum depreciation | M11: Cost As | O11: Disposals | Q11: Additions | S11: Cost As | U11: type of assets
A12: =CONCATENATE("AS at",Index!G5,"/",Index!J6,"/",Index!G7) -> AS at31/12/2023 | C12: =CONCATENATE("AS at",Index!J5,"/",Index!J6,"/",Index!J7) -> AS at31/12/2024 | E12: =+M12 -> At31/12/2024 | G12: Year | I12: Year | K12: =S12 -> At01/01/2024 | M12: =CONCATENATE("At",Index!J5,"/",Index!J6,"/",Index!J7) -> At31/12/2024 | O12: For Year | Q12: For Year | S12: =CONCATENATE("At",Index!K5,"/",Index!K6,"/",Index!K7) -> At01/01/2024
A13: =S13-K13 -> 0 | C13: =M13-E13 -> 0 | E13: =K13+I13-G13 -> 0 | G13: 0 | I13: 0 | K13: 0 | M13: =S13+Q13-O13 -> 0 | O13: 0 | Q13: 0 | S13: 0
A14: =S14-K14 -> 0 | C14: =M14-E14 -> 0 | E14: =K14+I14-G14 -> 0 | G14: 0 | I14: 0 | K14: 0 | M14: =S14+Q14-O14 -> 0 | O14: 0 | Q14: 0 | S14: 0
A15: =SUM(A13:A14) -> 0 | C15: =SUM(C13:C14) -> 0 | E15: =SUM(E13:E14) -> 0 | F15: =SUM(F13:F14) -> 0 | G15: =SUM(G13:G14) -> 0 | H15: =SUM(H13:H14) -> 0 | I15: =SUM(I13:I14) -> 0 | K15: =SUM(K13:K14) -> 0 | M15: =SUM(M13:M14) -> 0 | O15: =SUM(O13:O14) -> 0 | Q15: =SUM(Q13:Q14) -> 0 | S15: =SUM(S13:S14) -> 0 | U15: Total
S39: ='Balance Sheet'!K13 -> Intangible assets | V39: ='Balance Sheet'!H13&"-" -> -
U40: =S39&" "&"As at" &Index!$H$5&" "&Index!$H$6&" "&" :" -> Intangible assets As at31 December :
A42: =+A11 -> Net book amounts | B42: =+B11 -> 0 | C42: =+C11 -> Net book amounts | D42: =+D11 -> 0 | E42: Accum amortization | F42: =+F11 -> 0 | G42: =+G11 -> Disposals | H42: =+H11 -> 0 | I42: amortization | J42: =+J11 -> 0 | K42: Accum amortization | L42: =+L11 -> 0 | M42: =+M11 -> Cost As | N42: =+N11 -> 0 | O42: =+O11 -> Disposals | P42: =+P11 -> 0 | Q42: =+Q11 -> Additions | R42: =+R11 -> 0 | S42: =+S11 -> Cost As | W42: amortization
A43: =A12 -> AS at31/12/2023 | C43: =C12 -> AS at31/12/2024 | E43: =E12 -> At31/12/2024 | G43: =+G12 -> Year | I43: =+I12 -> Year | K43: =K12 -> At01/01/2024 | M43: =M12 -> At31/12/2024 | O43: =+O12 -> For Year | Q43: =+Q12 -> For Year | S43: =S12 -> At01/01/2024
A44: =S44-K44 -> 0 | C44: =M44-E44 -> 0 | E44: =K44+I44-G44 -> 0 | M44: =S44+Q44-O44 -> 0
A46: =SUM(A44) -> 0 | C46: =SUM(C44) -> 0 | E46: =SUM(E44:E45) -> 0 | G46: =SUM(G44:G45) -> 0 | I46: =SUM(I44:I45) -> 0 | K46: =SUM(K44:K45) -> 0 | M46: =SUM(M44:M45) -> 0 | O46: =SUM(O44:O45) -> 0 | Q46: =SUM(Q44:Q45) -> 0 | R46: =SUM(#REF!) -> #REF! | S46: =SUM(S44:S45) -> 0 | U46: Total
S48: ='Balance Sheet'!K14&":" -> Leasing Assets (net): | V48: ='Balance Sheet'!H14&"-" -> -
U49: =S48&" "&"As at" &Index!$H$5&" "&Index!$H$6&" "&" :" -> Leasing Assets (net): As at31 December :
A51: =+A11 -> Net book amounts | B51: =+B11 -> 0 | C51: =+C11 -> Net book amounts | D51: =+D11 -> 0 | E51: =+E11 -> Accum depreciation | F51: =+F11 -> 0 | G51: =+G11 -> Disposals | H51: =+H11 -> 0 | ... S51: =+S11 -> Cost As
A52: =+A12 -> AS at31/12/2023 | C52: =+C12 -> AS at31/12/2024 | E52: =+E12 -> At31/12/2024 | G52: =+G12 -> Year | I52: =+I12 -> Year | K52: =+K12 -> At01/01/2024 | M52: =+M12 -> At31/12/2024 | O52: =+O12 -> For Year | Q52: =+Q12 -> For Year | S52: =+S12 -> At01/01/2024
A53: =S53-K53 -> 0 | C53: =M53-E53 -> 0 | E53: =K53+I53-G53 -> 0 | M53: =S53+Q53-O53 -> 0
A55: =SUM(A53) -> 0 | C55: =SUM(C53) -> 0 | E55: =SUM(E53:E54) -> 0 | G55: =SUM(G53:G54) -> 0 | I55: =SUM(I53:I54) -> 0 | K55: =SUM(K53:K54) -> 0 | M55: =SUM(M53:M54) -> 0 | O55: =SUM(O53:O54) -> 0 | Q55: =SUM(Q53:Q54) -> 0 | R55: =SUM(#REF!) -> #REF! | S55: =SUM(S53:S54) -> 0 | U55: Total
U57: ='Balance Sheet'!K15&":" -> Investment property: | V57: ='Balance Sheet'!H15&"-" -> -
U58: =U57&" "&"As at" &Index!$H$5&" "&Index!$H$6&" "&" :" -> Investment property: As at31 December :
A60: =+A11 -> Net book amounts | B60: =+B11 -> 0 | C60: =+C11 -> Net book amounts | D60: =+D11 -> 0 | E60: =+E11 -> Accum depreciation | F60: =+F11 -> 0 | G60: =+G11 -> Disposals | H60: =+H11 -> 0 | ... S60: =+S11 -> Cost As
A61: =A12 -> AS at31/12/2023 | C61: =C12 -> AS at31/12/2024 | E61: =E52 -> At31/12/2024 | G61: =+G12 -> Year | I61: =+I12 -> Year | K61: =K52 -> At01/01/2024 | M61: =M52 -> At31/12/2024 | O61: =+O12 -> For Year | Q61: =+Q12 -> For Year | S61: =S52 -> At01/01/2024
A62: =S62-K62 -> 0 | C62: =M62-E62 -> 0 | E62: =K62+I62-G62 -> 0 | G62: 0 | M62: =S62+Q62-O62 -> 0
A64: =SUM(A62) -> 0 | C64: =SUM(C62) -> 0 | E64: =SUM(E62:E63) -> 0 | G64: =SUM(G62:G63) -> 0 | I64: =SUM(I62:I63) -> 0 | K64: =SUM(K62:K63) -> 0 | M64: =SUM(M62:M63) -> 0 | O64: =SUM(O62:O63) -> 0 | Q64: =SUM(Q62:Q63) -> 0 | R64: =SUM(#REF!) -> #REF! | S64: =SUM(S62:S63) -> 0 | U64: Total
U66: * Investment property is not measured at fair value on each reporting date, as a result of measuring its fair value in a reliable manner from an undue cost and effort..
A67: ="-"&SUM(Index!I10:I20)&"-" -> -11-

Sheet D
A1: =Cover!A14 -> 0
A2: =Cover!A15 -> (Foreign Company – Limited Liability Company)
A3: =Cover!A16 -> Riyadh – Kingdom of Saudi Arabia
A4: ='1'!B4 -> NOTES TO THE FINANCIAL STATEMENTS FOR PERIOD ENDED31December2024
A5: ='Balance Sheet'!A5 -> (saudi riyal)
H7: ='Balance Sheet'!K16 -> Capital work in progress | K7: ='Balance Sheet'!H16&"-" -> -
B8: =H7&" "&"in" &Index!$H$5&" "&Index!$H$6&" "&" :" -> Capital work in progress in31 December :
C9: =Index!$G$5&Index!$G$6&Index!$G$7 -> 31December2023 | E9: =Index!$H$5&Index!$H$6&Index!$H$7 -> 31December2024
C10: ='Balance Sheet'!$D$10 -> (saudi riyal) | E10: ='Balance Sheet'!$F$10 -> (saudi riyal)
C12: 0 | E12: 0 | H12: Capital work in progress
C13: =SUM(C11:C12) -> 0 | E13: =SUM(E11:E12) -> 0 | H13: ="Balance ended "&"For "&Index!J2 -> Balance ended For YEAR
H15: ='Balance Sheet'!K17 -> Investments in Subsidiaries | K15: ='Balance Sheet'!H17&"-" -> -
B16: =H15&" "&"in" &Index!$H$5&" "&Index!$H$6&" "&" :" -> Investments in Subsidiaries in31 December :
C17: =Index!$G$5&Index!$G$6&Index!$G$7 -> 31December2023 | E17: =Index!$H$5&Index!$H$6&Index!$H$7 -> 31December2024
C18: ='Balance Sheet'!$D$10 -> (saudi riyal) | E18: ='Balance Sheet'!$F$10 -> (saudi riyal)
C20: 0 | E20: 0 | H20: Fluorite Valves Company
C21: =SUM(C19:C20) -> 0 | E21: =SUM(E19:E20) -> 0 | H21: =$H$13 -> Balance ended For YEAR
H23: ='Balance Sheet'!K21 -> Inventories | K23: ='Balance Sheet'!H21&"-" -> -
B24: =H23&" "&"in" &Index!$H$5&" "&Index!$H$6&" "&" :" -> Inventories in31 December :
C25: =Index!$G$5&Index!$G$6&Index!$G$7 -> 31December2023 | E25: =Index!$H$5&Index!$H$6&Index!$H$7 -> 31December2024
C26: ='Balance Sheet'!$D$10 -> (saudi riyal) | E26: ='Balance Sheet'!$F$10 -> (saudi riyal)
C27: 0 | E27: 0 | H27: Inventories
C29: =SUM(C27:C28) -> 0 | E29: =SUM(E27:E28) -> 0 | H29: =$H$13 -> Balance ended For YEAR
H31: ='Balance Sheet'!K22 -> Trade receivables | K31: ='Balance Sheet'!H22&"-" -> 5-
B32: =H31&" "&"in" &Index!$H$5&" "&Index!$H$6&" "&" :" -> Trade receivables in31 December :
C33: =Index!$G$5&Index!$G$6&Index!$G$7 -> 31December2023 | E33: =Index!$H$5&Index!$H$6&Index!$H$7 -> 31December2024
C34: ='Balance Sheet'!$D$10 -> (saudi riyal) | E34: ='Balance Sheet'!$F$10 -> (saudi riyal)
C36: 0 | E36: 0 | H36: Trade receivables
C37: 0 | E37: 0 | H37: (Deduct) the provision for doubtful debts
C38: =SUM(C35:C37) -> 0 | E38: =SUM(E35:E37) -> 0 | H38: =$H$13 -> Balance ended For YEAR
F40: ='Balance Sheet'!K23 -> Prepayments and other receivables | K40: ='Balance Sheet'!H23&"-" -> 6-
B41: =F40&" "&"in" &Index!$H$5&" "&Index!$H$6&" "&" :" -> Prepayments and other receivables in31 December :
C42: =Index!$G$5&Index!$G$6&Index!$G$7 -> 31December2023 | E42: =Index!$H$5&Index!$H$6&Index!$H$7 -> 31December2024
C43: ='Balance Sheet'!$D$10 -> (saudi riyal) | E43: ='Balance Sheet'!$F$10 -> (saudi riyal)
C45: 0 | E45: 0 | H45: prepaid expenses
C46: 0 | E46: 0 | H46: employees' receivables and advances
C47: 0 | E47: 0 | H47: guarantee plan insurance
C48: 0 | E48: 0 | H48: insurance with third parties
C49: 0 | E49: 0 | H49: other debit balances
C50: =SUM(C44:C49) -> 0 | E50: =SUM(E44:E49) -> 0 | H50: =$H$13 -> Balance ended For YEAR
...

Sheet م ا
A1: =Cover!A14 -> 0
A2: =Cover!A15 -> (Foreign Company – Limited Liability Company)
A3: =Cover!A16 -> Riyadh – Kingdom of Saudi Arabia
A4: ='1'!B4 -> NOTES TO THE FINANCIAL STATEMENTS FOR PERIOD ENDED31December2024
A10: ='Balance Sheet'!H24&"-"&'Balance Sheet'!K24 -> 9- Related parties
A12: إن الأطراف ذات العلاقة هي المنشآت المرتبطة بالمنشأة والموظفين الرئيسيين بها والمنشآت الأخرى المسيطر عليها بالكامل أو بشكل مشترك من قبل هذه الأطراف أو التي تمارس نفوذاً هاماً عليها وتتمثل المعاملات مع أطراف ذات علاقة في الدفعات المقدمة الى تلك الاطراف ، ولا يوجد جدول محدد لإعادة سداد تلك المبالغ كما أنه لا يترتب على سدادها أية أعباء تمويلية وفيما يلي أرصدة أطراف ذوي علاقة كما في 31 ديسمبر فيما يلي:
A14: البيـــــــان | B14: طبيعة التعامل | C14: الرصيد الافتتاحي | E14: الحركة خلال السنة | G14: الرصيد النهائي
C15: مدين | D15: دائن | E15: مدين | F15: دائن | G15: مدين | H15: دائن
A16: دكتور بدر النفسية | C16: 0 | D16: 0 | G16: =+C16-D16+E16-F16 -> 0 | H16: 0
A17: دكتور ابراهيم خالد | C17: 0 | D17: 0 | G17: =+C17-D17+E17-F17 -> 0 | H17: 0
A18: على عبدالله بن هليل | C18: 0 | D18: 0 | G18: =+C18-D18+E18-F18 -> 0 | H18: 0
A19: الاجمالي | C19: =SUM(C16:C17) -> 0 | D19: =SUM(D16:D17) -> 0 | E19: =SUM(E16:E17) -> 0 | F19: =SUM(F16:F17) -> 0 | G19: =SUM(G16:G18) -> 0 | H19: =SUM(H16:H17) -> 0
A26: 13- رأس المال :
A27: حدد رأسمال الشركة بـ ( 150.000 ) ريال مقسم إلى ( 100) حصة عينية متساوية القيمة ، قيمة كل حصة ( 1500 ) ريال تم توزيعها على الشركاء على النحو التالي :
A28: اسم الشريك | C28: عدد الحصص | E28: قيمة الحصة | G28: الإجمالي | I28: النسبة المئوية
A29: مؤسسة متاجرة الأعمال للتجارة | C29: 90 | E29: 1500 | G29: =+E29*C29 -> 135000 | I29: =G29/G34 -> 0.9
A30: مؤسسة مدار الأعمال التجارية | C30: 10 | E30: 1500 | G30: =+E30*C30 -> 15000 | I30: =+G30/G34 -> 0.1
A34: الاجمالي | C34: =SUM(C29:D33) -> 100 | E34: =E29 -> 1500 | G34: =SUM(G29:H33) -> 150000 | I34: 1
A36: ="-"&SUM(Index!I10:I21)&"-" -> -12-

Sheet L
A1: =Cover!A14 -> 0
A2: =Cover!A15 -> (Foreign Company – Limited Liability Company)
A3: =Cover!A16 -> Riyadh – Kingdom of Saudi Arabia
A4: ='1'!B4 -> NOTES TO THE FINANCIAL STATEMENTS FOR PERIOD ENDED31December2024
A6: ='Balance Sheet'!H32&"-"&'Balance Sheet'!K32 -> 8-capital
A7: The company’s capital is set at (100,000) SAR, divided into (1,000) equal cash shares, each valued at (100) Saudi Riyals. The shares were distributed among the partners as follows:
A8: Partner Name | D8: Number of shares | F8: Share value | H8: Total | J8: النسبة المئوية
A9: 0 | D9: 1000 | F9: 100 | H9: =+F9*D9 -> 100000 | J9: =H9/H11 -> 1
D10: 0 | F10: 1000 | H10: =+F10*D10 -> 0 | J10: =+H10/H11 -> 0 | L10: FLORIGHT
A11: Total | D11: =SUM(D9:E10) -> 1000 | F11: =F9 -> 100 | H11: =SUM(H9:I10) -> 100000 | J11: 1
A13: ='Balance Sheet'!H39&"-"&'Balance Sheet'!K39 -> 9-Credit Related parties
A14: The related parties are the entities associated with the entity, its key employees and other entities that are wholly or jointly controlled by, or have significant influence over, the parties. Transactions with related parties consist of payments from by those parties to support the operations of the entity and its working capital. A fixed schedule for the repayment of these amounts and the payment of which does not entail any financial burdens. The balances of related parties as of December 31 are as follows:
A16: The related parties Name | B16: nature Relationship | C16: Nature of transactions | D16: Opening balance | F16: Movement during the period | H16: Ending Balance
D17: debit | E17: Credit | F17: debit | G17: Credit | H17: debit | I17: Credit
A18: 0 | B18: Partner | C18: finance | D18: 0 | E18: 0 | F18: 0 | G18: 0 | H18: 0 | I18: =E18-F18+G18 -> 0
B19: Related by Partner | C19: finance | D19: 0 | E19: 0 | F19: 0 | G19: 0 | H19: 0 | I19: =+E19+G19-F19-D19 -> 0
B20: Partner | C20: finance | D20: 0 | E20: 0 | F20: 0 | G20: 0 | H20: 0 | I20: =+E20+G20-F20-D20 -> 0
A21: Total | D21: =SUM(D18:D20) -> 0 | E21: =SUM(E18:E20) -> 0 | F21: =SUM(F18:F20) -> 0 | G21: =SUM(G18:G20) -> 0 | H21: =SUM(H18:H20) -> 0 | I21: =SUM(I18:I20) -> 0
A24: ="-"&SUM(Index!I10:I23)&"-" -> -13-

Sheet C
B1: =Cover!A14 -> 0
B2: =Cover!A15 -> (Foreign Company – Limited Liability Company)
B3: =Cover!A16 -> Riyadh – Kingdom of Saudi Arabia
B4: ='1'!B4 -> NOTES TO THE FINANCIAL STATEMENTS FOR PERIOD ENDED31December2024
B5: ='Balance Sheet'!A5 -> (saudi riyal)
I7: ='Balance Sheet'!K40 -> Provision for Employees' benefits | L7: ='Balance Sheet'!H40&"-" -> 10-
C8: =I7&" "&"in" &Index!$H$5&" "&Index!$H$6&" "&" :" -> Provision for Employees' benefits in31 December :
B9: =Index!$F$5&Index!$F$6&Index!$F$7 -> 01January2017 | D9: =Index!$G$5&Index!$G$6&Index!$G$7 -> 31December2023 | F9: =Index!$H$5&Index!$H$6&Index!$H$7 -> 31December2024
B10: ='Balance Sheet'!$D$10 -> (saudi riyal) | D10: ='Balance Sheet'!$D$10 -> (saudi riyal) | F10: ='Balance Sheet'!$F$10 -> (saudi riyal)
B11: 8234 | D11: 0 | F11: =D14 -> 0 | I11: Balance beginning of yaer
B12: 17217 | D12: 0 | F12: 0 | I12: addition
B13: 0 | D13: 0 | F13: 0 | I13: payment
B14: =SUM(B11:B13) -> 25451 | D14: =SUM(D11:D13) -> 0 | F14: =SUM(F11:F13) -> 0 | I14: =D!$H$13 -> Balance ended For YEAR
K18: Employee benefits at December 31 consist of the following:
D19: =Index!$G$5&Index!$G$6&Index!$G$7 -> 31December2023 | F19: =Index!$H$5&Index!$H$6&Index!$H$7 -> 31December2024
D21: 0 | F21: 0 | I21: Balance at the beginning of the year
D22: 0 | F22: 0 | I22: component during the year
D23: 0 | F23: 0 | I23: actuarial losses*
D24: 0 | F24: 0 | I24: Paid during the year
D25: =SUM(D21:D24) -> 0 | F25: =SUM(F21:F24) -> 0 | I25: Balance at the end of the period
K27: The significant assumptions used in determining the employee benefit obligations are as follows: | L27: *
D28: =D19 -> 31December2023 | F28: =F19 -> 31December2024
D29: 0.028 | F29: 0.0196 | I29: Discount rate
D30: 0.07 | F30: 0.07 | I30: Future salary increase rate
D31: 60 سنة | F31: 60 سنة | I31: retirement age
K33: Sensitivity analysis:
D34: The results are affected by the assumptions used, especially the leaving service assumptions. The following table shows the change in the defined benefit obligations based on the increase or decrease in the value of the basic assumptions as on December 31, 2021:
B36: =Index!$F$5&Index!$F$6&Index!$F$7 -> 01January2017 | F36: The increase in assumptions | H36: change in assumptions | K36: Statement
B37: ='Balance Sheet'!$D$10 -> (saudi riyal) | F37: 0.0196 | H37: 0.0084 | K37: Discount rate
F38: 0.07 | H38: 0 | K38: Leaving Rate
D39: The company’s management recalculated the provision for employee benefits as on December 31, 2021, in accordance with the human resources system, and it had no effect on the year, as this difference is charged to comprehensive income as on December 31, 2021. | L39: *
B45: =SUM(B38:B39) -> 0 | D45: =SUM(D38:D39) -> 0 | F45: =SUM(F38:F39) -> 0.07 | I45: =D!$H$13 -> Balance ended For YEAR
L46: Leasing amount
B47: 0 | D47: 0 | F47: 0 | J47: Lees of Year
B48: 0 | D48: 0 | F48: 0 | J48: From year to 5 Years
B49: 0 | D49: 0 | F49: 0 | J49: After 5 Years
I51: ='Balance Sheet'!K42 -> Deferred income | L51: ='Balance Sheet'!H42&"-" -> 19-
C52: =I51&" "&"in" &Index!$H$5&" "&Index!$H$6&" "&" :" -> Deferred income in31 December :
B53: =Index!$F$5&Index!$F$6&Index!$F$7 -> 01January2017 | D53: =Index!$G$5&Index!$G$6&Index!$G$7 -> 31December2023 | F53: =Index!$H$5&Index!$H$6&Index!$H$7 -> 31December2024 | K53: =G!G1 -> 0
B54: ='Balance Sheet'!$D$10 -> (saudi riyal) | D54: ='Balance Sheet'!$D$10 -> (saudi riyal) | F54: ='Balance Sheet'!$F$10 -> (saudi riyal)
...

Sheet P
I8: ='Balance Sheet'!K47 -> Short-term leasing creditors | L8: ='Balance Sheet'!H47&"-" -> 22-
B9: =I8&" "&"in" &Index!$H$5&" "&Index!$H$6&" "&" :" -> Short-term leasing creditors in31 December :
B10: =Index!$G$5&Index!$G$6&Index!$G$7 -> 31December2023 | D10: =Index!$H$5&Index!$H$6&Index!$H$7 -> 31December2024
B11: ='Balance Sheet'!$D$10 -> (saudi riyal) | D11: ='Balance Sheet'!$F$10 -> (saudi riyal)
B14: =SUM(B12:B13) -> 0 | D14: =SUM(D12:D13) -> 0 | J14: =D!$H$13 -> Balance ended For YEAR
I16: ='Balance Sheet'!K48 -> Provision for income tax | L16: ='Balance Sheet'!H48 &"-" -> 13-
D18: =Index!$H$5&Index!$H$6&Index!$H$7 -> 31December2024 | K18: =" Its Calculate from "&S!J8&" "&"As at" &" "&Index!H5&""&Index!H6&":" -> Its Calculate from Provision for income tax As at 31December: | L18: A)
B19: =Index!$G$5&Index!$G$6&Index!$G$7 -> 31December2023 | D19: ='Balance Sheet'!$F$10 -> (saudi riyal)
B20: ='Income Statement'!B21 -> 0 | D20: ='Income Statement'!D21 -> 0 | K20: income before income tax
B21: ='C'!D14 -> 0 | D21: ='C'!F14 -> 0 | K21: provisions charged to the period accounts
D22: 0 | K22: consumption differences
D23: 0 | K23: fines and penalties
D24: 0 | K24: owner’s salaries
D25: 0 | K25: non-deductible expenses
D26: 0 | K26: amounts paid from provisions during the period
D27: 0 | K27: deductions from carried-forward losses
D28: =SUM(D20:D27) -> 0 | I28: adjusted net profit
B29: =B28*0.2 -> 0 | D29: =D28*0.2 -> 0 | I29: income tax
B32: =Index!$G$5&Index!$G$6&Index!$G$7 -> 31December2023 | D32: =Index!$H$5&Index!$H$6&Index!$H$7 -> 31December2024 | J32: movement of Provision | L32: B)
B33: ='Balance Sheet'!$D$10 -> (saudi riyal) | D33: ='Balance Sheet'!$F$10 -> (saudi riyal)
B34: 0 | D34: 0 | I34: Balance beginning of yaer
B35: 0 | D35: 0 | I35: adjustment
B36: =TRUNC(B29,0) -> 0 | D36: =TRUNC(D29,0) -> 0 | I36: addition
B37: 0 | D37: 0 | I37: payment
B38: =SUM(B34:B37) -> 0 | D38: =SUM(D34:D37) -> 0 | K38: =D!$H$13 -> Balance ended For YEAR
K40: income tax position: | L40: p)
B41: The company settled its zakat position with the General Authority of Zakat and Income according to Zakat Certificate No. 3104614357 dated 09/28/1443 AH. This certificate is valid until 10/10/1444 AH corresponding to 04-30-2023 AD.

Sheet P2
B3: شرح عناصر الوعاء للزكاة الشرعية
D7: العناصر الموجبة
B9: ='Partners Equity'!F27 -> 0 | C9: راس المال
B10: =IF(('Balance Sheet'!D35+'Partners Equity'!C23)>0,'Partners Equity'!C20+'Partners Equity'!C23+'Partners Equity'!C25,0) -> 0 | C10: الارباح المبقاه
B11: 0 | C11: اطراف ذات علاقة دائنة
B12: ='Partners Equity'!E27 -> 0 | C12: الاحتياطى النظامى
B13: =+'C'!F11+'C'!F13 -> 0 | D13: مخصص مكافاة نهاية الخدمة
B14: 0 | D14: مخصص الزكاة الشرعية
B15: ='Partners Equity'!E10 -> 0
B16: 0 | C16: راس مال إضافي
B19: =SUM(B8:B18) -> 0 | C19: إجمالي العناصر الموجبة
D21: العناصر السالبة
B25: ='Balance Sheet'!F12 -> 0 | C25: الموجودات الثابتة (بالصافى)
B26: 0 | C26: الخسائر المبقاه
D27: اطراف ذات علاقة مدينة
B28: =-'C'!F13 -> 0 | D28: مخصص منافع الموظفين المستخدم
B31: =SUM(B22:B30) -> 0 | C31: إجمالي العناصر السالبة

Sheet S
B1: =Cover!A14 -> 0
B2: =Cover!A15 -> (Foreign Company – Limited Liability Company)
B3: =Cover!A16 -> Riyadh – Kingdom of Saudi Arabia
B4: ='1'!B4 -> NOTES TO THE FINANCIAL STATEMENTS FOR PERIOD ENDED31December2024
B5: ='Balance Sheet'!A5 -> (saudi riyal)
J8: ='Balance Sheet'!K48 -> Provision for income tax | K8: ='Balance Sheet'!H48&"-" -> 13-
B10: The zakat was calculated for the institution in an estimation, due to the incomplete year of the institution, and when the institution was converted into a company, the zakat was calculated at an amount of 16,076 riyals.
C14: =+'Income Statement'!$D$7 -> For the Period Ended 31 December 2024 | E14: =+'Income Statement'!$D$7 -> For the Period Ended 31 December 2024 | H14: ='Income Statement'!G10 -> Revenue | K14: ='Income Statement'!F10&"-" -> 14-
C15: ='Balance Sheet'!$F$10 -> (saudi riyal) | E15: ='Balance Sheet'!$F$10 -> (saudi riyal) | J15: =H14&" "&"in" &Index!$H$5&" "&Index!$H$6&" "&" :" -> Revenue in31 December :
C17: 0 | E17: 0 | H17: revenue
C18: =SUM(C17:C17) -> 0 | E18: =SUM(E17:E17) -> 0 | H18: Total
C22: =+'Income Statement'!$D$7 -> For the Period Ended 31 December 2024 | E22: =+'Income Statement'!$D$7 -> For the Period Ended 31 December 2024 | H22: ='Income Statement'!G12 -> Cost of Revenue | K22: ='Income Statement'!F15&"-" -> 15-
C23: ='Balance Sheet'!$F$10 -> (saudi riyal) | E23: ='Balance Sheet'!$F$10 -> (saudi riyal) | J23: =H22&" "&"in" &Index!$H$5&" "&Index!$H$6&" "&" :" -> Cost of Revenue in31 December :
C25: 0 | E25: 0 | J25: Cost of Goods Sold
C26: 0 | E26: 0 | G26: 15/1 | J26: Operating Expenses
C27: =SUM(C25:C26) -> 0 | E27: =SUM(E25:E26) -> 0 | J27: =+S!J35 -> Total
C29: =+'Income Statement'!$D$7 -> For the Period Ended 31 December 2024 | E29: =+'Income Statement'!$D$7 -> For the Period Ended 31 December 2024 | J29: =J26 -> Operating Expenses | K29: =G26 -> 15/1
C30: ='Balance Sheet'!$F$10 -> (saudi riyal) | E30: ='Balance Sheet'!$F$10 -> (saudi riyal) | H30: =J29&" "&"in" &Index!$H$5&" "&Index!$H$6&" "&" :" -> Operating Expenses in31 December :
C33: 0 | E33: 0 | I33: Shipping and Transportation Expenses
C34: 0 | E34: 0 | I34: Bonuses and Incentives
C35: =SUM(C33:C34) -> 0 | E35: =SUM(E33:E34) -> 0 | J35: =S!H18 -> Total
B39: ="-"&SUM(Index!I10:I26)&"-" -> -16-

Sheet G
A1: =Cover!A14 -> 0
A2: =Cover!A15 -> (Foreign Company – Limited Liability Company)
A3: =Cover!A16 -> Riyadh – Kingdom of Saudi Arabia
A4: ='1'!B4 -> NOTES TO THE FINANCIAL STATEMENTS FOR PERIOD ENDED31December2024
A5: ='Balance Sheet'!A5 -> (saudi riyal)
G8: ='Income Statement'!G16 -> General and administrative expenses | J8: ='Income Statement'!F16&"-" -> 16-
H9: =G8&" "&"in" &Index!$H$5&" "&Index!$H$6&" "&" :" -> General and administrative expenses in31 December :
B10: ='Income Statement'!$B$7 -> prieod from 5 may to 31 december | D10: =+'Income Statement'!$D$7 -> For the Period Ended 31 December 2024
B11: ='Balance Sheet'!$D$10 -> (saudi riyal) | D11: ='Balance Sheet'!$F$10 -> (saudi riyal) | S11: ايجارات وسعي
B12: 0 | D12: 0 | G12: salaries and wages and similar expenses | S12: مصاريف حكومية
B13: 0 | D13: 0 | G13: social insurance | L13: 240840 | S13: اهلاكات الاصول الثابتة
B14: 0 | D14: 0 | G14: government fees and subscriptions | L14: 20340 | N14: 0 | P14: =32148+7893+5591 -> 45632 | S14: مصروفات سيارات
B15: 0 | D15: 0 | G15: end-of-service gratuity expenses | L15: 0 | N15: 0 | P15: =30980+7668 -> 38648 | S15: صيانة واصلاح
B16: 0 | D16: 0 | G16: stationery and printing | L16: 0 | S16: تامينات الاجتماعية
B17: 0 | D17: 0 | G17: postage, telephone, and internet
B18: 0 | D18: 0 | G18: travel tickets and transportation | N18: 0 | S18: م نقل وشحن
B19: 0 | D19: 0 | G19: banking expenses and commissions
B20: 0 | D20: 0 | G20: other expenses | N20: 0 | P20: 12000 | S20: دعاية وإعلان
B21: 0 | D21: 0 | G21: programming and maintenance expenses
B22: 0 | D22: 0 | G22: professional fees expenses
B23: 0 | D23: 0 | G23: depreciation of properties, buildings, and equipment
B24: =SUM(B12:B23) -> 0 | D24: =SUM(D12:D23) -> 0 | G24: =+S!H18 -> Total | N24: 0 | P24: =5709+895 -> 6604 | S24: مكتبية ومطبوعات
N25: 0 | P25: 1621 | S25: كهرباء ومياة
N26: 0 | P26: =71 -> 71 | S26: رسوم بنكية وعمولات
A42: ="-"&SUM(Index!I10:I27)&"-" -> -17-

Sheet ورقة2

Sheet ورقة1

Sheet z
B1: =Cover!A14 -> 0
B2: =Cover!A15 -> (Foreign Company – Limited Liability Company)
B3: =Cover!A16 -> Riyadh – Kingdom of Saudi Arabia
B4: ='1'!B4 -> NOTES TO THE FINANCIAL STATEMENTS FOR PERIOD ENDED31December2024
B5: ='Balance Sheet'!A5 -> (saudi riyal)
H9: Financial instruments and risk management | K9: =('Income Statement'!F16+1)&"-" -> 17-
A10: The Group's activities expose it to several financial risks: market risk (including currency risk, fair value and cash flows, interest rate risk, credit risk and liquidity risk). The entity's overall risk management program focuses on the volatility of financial markets and seeks to minimize the potential negative impact on the financial performance of the entity. The main types of risk are summarized below:
H12: Currency risk | K12: A-
A13: Foreign exchange risk represents the risk of change in the value of financial instruments as a result of foreign currency fluctuations. All entity transactions are denominated in Saudi Riyals and consequently the entity's activity is not exposed to currency risk.
J15: Interest rate risk on cash flows and fair value | K15: B-
A16: Is the exposure to various risks related to the volatility of market interest rates on the financial position and cash flows of the entity. The entity has no interest rate risk on its cash flows and fair value.
H18: Credit risk | K18: C-
A19: Credit risk is the inability of the counterparty to meet its obligations to the entity, causing the other party to incur a financial loss. The entity has no significant concentration of credit risk. Cash is deposited with banks with a sound credit rating..
H22: Liquidity risk | K22: D-
A23: Is the risk that an entity will not be able to secure the liquidity required to meet liabilities relating to financial instruments. Liquidity risk may result from the inability to sell financial assets quickly and at fair value. Liquidity risk is managed by periodically ensuring that sufficient liquidity is available to meet any obligations in the future.
N26: H-
H27: Fair value | K27: H-
A28: Fair value is the amount at which an asset is exchanged or a liability settled between knowledgeable parties and willing to do so under normal conditions. The entity's financial instruments are grouped on a historical cost basis and differences can arise between book value and fair value estimates. Management considers that the fair values of the financial assets of the entity and its financial liabilities are not materially different from their carrying values.
H30: force continuity | J30: force continuity | K30: 19-
