Workbook
Name ReportCreated: TRUE

Sheet العملاء
B1: Abdullah Mansour Al-Subaie Company, Accountants and Legal Auditors, License No. (1031) | I1: Prepared By : | J1: saad
I2: Reviewed By :
B3: clint name
B4: year | C4: 45657
B5: Currency | C5: SAR
B8: Trade Receivable
B10: Description | D10: Balance as at | E10: Balance as at | F10: Variance | H10: Confirmations | J10: Subsequent period repayments | L10: Inovice checked
D11: =C4 -> 45657 | E11: 2023 Dec 31 | F11: SAR | G11: % | H11: SAR | I11: % | J11: SAR | K11: % | L11: SAR | M11: %
B12: Trade receivables | D12: 0 | E12: 0 | F12: =D12-E12 -> 0 | G12: =E12/F12 -> #DIV/0! | H12: =F56 -> 0 | I12: =H12/D12 -> #DIV/0! | J12: =E73 -> 0 | K12: =J12/B12 -> #VALUE! | L12: =D244 -> 0 | M12: =L12/D12 -> #DIV/0!
B13: Provision for doubtful debts | D13: 0 | E13: 0 | F13: =D13-E13 -> 0 | G13: =E13/F13 -> #DIV/0! | H13: 0 | I13: =H13/D13 -> #DIV/0! | J13: 0 | K13: =J13/B13 -> #VALUE! | L13: 0 | M13: =L13/D13 -> #DIV/0!
B14: end balance | D14: =SUM(D12:D13) -> 0 | E14: =SUM(E12:E13) -> 0 | F14: =SUM(F12:F13) -> 0 | G14: =E14/F14 -> #DIV/0! | H14: =SUM(H12:H13) -> 0 | I14: =SUM(I12:I13) -> #DIV/0! | J14: =SUM(J12:J13) -> 0 | K14: =J14/B14 -> #VALUE! | L14: =SUM(L12:L13) -> 0 | M14: =L14/D14 -> #DIV/0!
B17: Nature of dealing:
B18: Accounts receivable are transactions with customers in exchange for providing a service to the customer and issuing an invoice for it.
B22: Work Done
B23: 1) The matching of the opening balance for the comparative year was verified | EC23: The matching of the opening balance for the comparative year was verified
B24: 2) A table of accounts receivable balances was taken from the client, and the equations and final calculation of the final balance were verified. | EC24: A table of accounts receivable balances was taken from the client, and the equations and final calculation of the final balance were verified.
B25: 3) The reconciliation of the analytical GL with the trial balance and financial statements has been verified. | EC25: The reconciliation of the analytical account statements with the trial balance and financial statements has been verified.
B26: 4) Matched invoices from sales GL with Trade Receivable Checked Invoices | EC26: Matched invoices from sales GL with Trade Receivable Checked Invoices
B27: 5)The reconciliation of the GL with the accounts receivable confirmations has been verified. | EC27: The reconciliation of the account statements with the accounts receivable confirmations has been verified.
EC28: Confirmations were requested for the unresponded items, by obtaining statements for subsequent periods and samples such as invoices, bank transfers, or receipt vouchers.
B29: Alternative procedures
B30: 1) Confirmations were requested for the unresponded items, by obtaining statements for subsequent periods and samples such as invoices, bank transfers, or receipt vouchers.
B31: 2) تمت مطابقة مبلغ الفاتورة مع الرصيد المسجل
B32: 3) تم التحقق من دفع المبلغ في الفترة اللاحقة | EC32: Confirmations were requested for the unresponded items, by obtaining statements for subsequent periods and samples such as invoices, bank transfers, or receipt vouchers.
B35: Assertions | C35: Work Done
B36: Occurance | C36: Matched invoices from sales GL with Trade Receivable Checked Invoices
B37: Completenes | C37: The reconciliation of the analytical account statements with the trial balance and financial statements has been verified.
B38: Cut off | C38: Confirmations were requested for the unresponded items, by obtaining statements for subsequent periods and samples such as invoices, bank transfers, or receipt vouchers.
B39: Accuracy | C39: A table of accounts receivable balances was taken from the client, and the equations and final calculation of the final balance were verified.
B40: Classifcation | C40: The reclassification has been verified and presented in the financial statements
B41: Presentation | C41: The reclassification has been verified and presented in the financial statements
B45: Sample No. | C45: Customer's Name | D45: Category | E45: Amount December 2023 | F45: Confirmed Amount | G45: Difference | H45: Remarks
B46: 1 | D46: client | E46: 0 | F46: 0 | G46: =E46-F46 -> 0
B47: 2 | D47: client | E47: 0 | F47: =E47 -> 0 | G47: =E47-F47 -> 0
B48: 3 | D48: client | E48: 0 | F48: =E48 -> 0 | G48: =E48-F48 -> 0
B49: 4 | D49: client | E49: 0 | F49: =E49 -> 0 | G49: =E49-F49 -> 0
B50: 5 | D50: client | E50: 0 | F50: =E50 -> 0 | G50: =E50-F50 -> 0
B51: 6 | D51: client | E51: 0 | F51: =E51 -> 0 | G51: =E51-F51 -> 0
B52: 7 | D52: client | E52: 0 | F52: =E52 -> 0 | G52: =E52-F52 -> 0
B53: 8 | D53: client | E53: 0 | F53: =E53 -> 0 | G53: =E53-F53 -> 0
...

Sheet مخصص الديون المشكوك في تحصيلها 
B1: =العملاء!B1 -> Abdullah Mansour Al-Subaie Company, Accountants and Legal Auditors, License No. (1031)
B3: =العملاء!B3 -> clint name | C3: =العملاء!C3 -> 0
B4: =العملاء!B4 -> year | C4: =العملاء!C4 -> 45657
B5: =العملاء!B5 -> Currency | C5: =العملاء!C5 -> SAR
A8: # | B8: الاسم | C8: 0 الى 30 يوم | D8: 31 يوم الى 60 يوم | E8: 61 يوم الى 90 يوم | F8: 91 يوم الى 180 يوم | G8: 181 يوم الى 360 يوم | H8: الإجمالي | I8: رصيد المخصص | J8: التصفية في الفترة اللاحقة | K8: الملبلغ الراكد الذي لم تتم تسويته ولا توجد له فترات لاحقة
A9: 1 | C9: 0 | D9: 0 | E9: 0 | F9: 0 | G9: 0 | H9: =SUM(C9:G9) -> 0 | I9: 0 | J9: 0 | K9: =I9-J9 -> 0
A10: 2 | C10: 0 | D10: 0 | E10: 0 | F10: 0 | G10: 0 | H10: =SUM(C10:G10) -> 0 | I10: 0 | J10: 0 | K10: =I10-J10 -> 0
A11: 3 | C11: 0 | D11: 0 | E11: 0 | F11: 0 | G11: 0 | H11: =SUM(C11:G11) -> 0 | I11: 0 | J11: 0 | K11: =I11-J11 -> 0
A12: 4 | C12: 0 | D12: 0 | E12: 0 | F12: 0 | G12: 0 | H12: =SUM(C12:G12) -> 0 | I12: 0 | J12: 0 | K12: =I12-J12 -> 0
A13: 5 | C13: 0 | D13: 0 | E13: 0 | F13: 0 | G13: 0 | H13: =SUM(C13:G13) -> 0 | I13: 0 | J13: 0 | K13: =I13-J13 -> 0
A14: 6 | C14: 0 | D14: 0 | E14: 0 | F14: 0 | G14: 0 | H14: =SUM(C14:G14) -> 0 | I14: 0 | J14: 0 | K14: =I14-J14 -> 0
A15: 7 | C15: 0 | D15: 0 | E15: 0 | F15: 0 | G15: 0 | H15: =SUM(C15:G15) -> 0 | I15: 0 | J15: 0 | K15: =I15-J15 -> 0
A16: 8 | C16: 0 | D16: 0 | E16: 0 | F16: 0 | G16: 0 | H16: =SUM(C16:G16) -> 0 | I16: 0 | J16: 0 | K16: =I16-J16 -> 0
A17: 9 | C17: 0 | D17: 0 | E17: 0 | F17: 0 | G17: 0 | H17: =SUM(C17:G17) -> 0 | I17: 0 | J17: 0 | K17: =I17-J17 -> 0
A18: 10 | C18: 0 | D18: 0 | E18: 0 | F18: 0 | G18: 0 | H18: =SUM(C18:G18) -> 0 | I18: 0 | J18: 0 | K18: =I18-J18 -> 0
A19: 11 | C19: 0 | D19: 0 | E19: 0 | F19: 0 | G19: 0 | H19: =SUM(C19:G19) -> 0 | I19: 0 | J19: 0 | K19: =I19-J19 -> 0
A20: 12 | C20: 0 | D20: 0 | E20: 0 | F20: 0 | G20: 0 | H20: =SUM(C20:G20) -> 0 | I20: 0 | J20: 0 | K20: =I20-J20 -> 0
... A28: 20 | C28: 0 | D28: 0 | E28: 0 | F28: 0 | G28: 0 | H28: =SUM(C28:G28) -> 0 | I28: 0 | J28: 0 | K28: =I28-J28 -> 0
A29: الإجمالي | C29: =SUM(C9:C28) -> 0 | D29: =SUM(D9:D28) -> 0 | E29: =SUM(E9:E28) -> 0 | F29: =SUM(F9:F28) -> 0 | G29: =SUM(G9:G28) -> 0 | H29: =SUM(C29:G29) -> 0 | I29: =SUM(I9:I28) -> 0 | J29: =SUM(J9:J28) -> 0 | K29: =SUM(K9:K28) -> 0
B33: الرصيد الافتتاحي للمخصص
